Workbook

Sheet Respostas
A1: Desafio 2 — Propensão à conversão: respostas
A2: Abordagem descritiva (o case aceita): a propensão de cada contador é a taxa histórica de conversão de quem tem o mesmo perfil — média das taxas das categorias dele nos 5 drivers do top 5. Sem modelo e sem pesos; a lista completa está na aba Base (coluna AA).
A4: 1. Lógica — quais variáveis e por quê
A5: • Testadas 9 características. Entram as 5 que mais separam quem converte de quem não converte (amplitude = maior taxa − menor taxa, categorias com 30+ contadores). Região, segmento, site e LinkedIn quase não separam.
A6: • Fora: score_potencial_latente (regra do case) e status_omie (não tem sinal e diverge dos contratos).
A7: Endereçáveis (303) na faixa Alta de propensão | B7: =COUNTIFS(Base!$AB$2:$AB$601,"Alta",Base!$S$2:$S$601,1) -> 14
A8: • O topo da propensão já foi quase todo convertido: entre os 303 endereçáveis, poucos estão na faixa Alta.
A10: 2. Como avaliar se está funcionando — em duas etapas
A11: Etapa 1 (base): conversão por faixa — Alta · Média · Baixa (meta: Alta > Média > Baixa) | B11: =Como_Avaliar!C5 -> 91% · 29% · 3%
A12: Etapa 1 (base): % dos convertidos captados pelo top 30% (meta: acima de 30%) | B12: =Como_Avaliar!C6 -> 0.69166667
A13: Etapa 1 (base): win rate real — faixa Alta × demais (meta: Alta acima) | B13: =Como_Avaliar!C7 -> 60% × 65%
A14: Etapa 1 (base): ciclo médio do Ganho — faixa Alta × demais (meta: Alta ≤ demais) | B14: =Como_Avaliar!C10 -> 36 × 48 dias
A15: • Etapa 2 (piloto de 90 dias com grupo de controle): win rate, nMRR por EC e ciclo do grupo piloto melhores que os do controle. Se superar, a priorização vira processo; senão, o perfil é revisto.
A17: 3. Top 5 características (amplitude da taxa de conversão)
A18: ="1. "&INDEX(Drivers!$H$6:$H$14,MATCH(1,Drivers!$J$6:$J$14,0))&" — "&FIXED(INDEX(Drivers!$I$6:$I$14,MATCH(1,Drivers!$J$6:$J$14,0)),0)&" p.p.: Médio e Grande convertem 94–100%; Autônomo 7%" -> 1. Porte — 93 p.p.: Médio e Grande convertem 94–100%; Autônomo 7%
A19: ="2. "&INDEX(Drivers!$H$6:$H$14,MATCH(2,Drivers!$J$6:$J$14,0))&" — "&FIXED(INDEX(Drivers!$I$6:$I$14,MATCH(2,Drivers!$J$6:$J$14,0)),0)&" p.p.: de ~9% (1 a 2 funcionários) a ~97% (16+)" -> 2. Nº de funcionários — 89 p.p.: de ~9% (1 a 2 funcionários) a ~97% (16+)
A20: ="3. "&INDEX(Drivers!$H$6:$H$14,MATCH(3,Drivers!$J$6:$J$14,0))&" — "&FIXED(INDEX(Drivers!$I$6:$I$14,MATCH(3,Drivers!$J$6:$J$14,0)),0)&" p.p.: de ~10% (< 20 clientes) a ~98% (150+); é também o Fit do 1c e do Desafio 3" -> 3. Nº de clientes da carteira — 88 p.p.: de ~10% (< 20 clientes) a ~98% (150+); é também o Fit do 1c e do Desafio 3
A21: ="4. "&INDEX(Drivers!$H$6:$H$14,MATCH(4,Drivers!$J$6:$J$14,0))&" — "&FIXED(INDEX(Drivers!$I$6:$I$14,MATCH(4,Drivers!$J$6:$J$14,0)),0)&" p.p.: ERP de mercado converte muito mais que planilha, nenhum ou ContaAzul" -> 4. ERP atual — 59 p.p.: ERP de mercado converte muito mais que planilha, nenhum ou ContaAzul
A22: ="5. "&INDEX(Drivers!$H$6:$H$14,MATCH(5,Drivers!$J$6:$J$14,0))&" — "&FIXED(INDEX(Drivers!$I$6:$I$14,MATCH(5,Drivers!$J$6:$J$14,0)),0)&" p.p.: 16+ anos convertem mais que o dobro dos com < 8 anos" -> 5. Anos de mercado — 34 p.p.: 16+ anos convertem mais que o dobro dos com < 8 anos
A23: • Porte, funcionários e carteira medem o mesmo conceito (tamanho). Com o ERP, descrevem o perfil do topo (ICP: 50+ clientes, 6+ funcionários e ERP de mercado).
A25: 4. Extra — impacto em nMRR ao priorizar quem tem maior propensão
A26: Uplift no nMRR do canal — cenário base | B26: =Impacto_nMRR!C23 -> 0.25355191
A27: Faixa (conservador a otimista) | B27: =FIXED(Impacto_nMRR!B23*100,0)&"% a "&FIXED(Impacto_nMRR!D23*100,0)&"%" -> 10% a 46%
A28: nMRR incremental/mês nas franquias abaixo da meta (escala oficial, cenário base) | B28: =Impacto_nMRR!C24 -> 31440.437
A29: • Premissas: 50% da capacidade dos ECs vai para o top 30% do score; 40% do lift do topo vira Ganho real (fator de realização, hipótese); ticket = mrr_inicial médio; desconto de churn de 20,5%.
A30: • Teste de estresse: com fator de realização 0, o uplift é 0. O número só se confirma com o piloto.
A32: 5. Previsibilidade de receita: o que o pipeline atual deve gerar no próximo trimestre
A33: Método 1: pipeline aberto ponderado pela chance de fechar de cada estágio (Ganhos) | B33: =Previsao_Receita!D18 -> 6.8686177
A34: Método 2: run-rate histórico do CRM (Ganhos por trimestre) | B34: =Previsao_Receita!B29 -> 8.1111111
A35: nMRR esperado do pipeline no trimestre (R$, escala do CRM) | B35: =Previsao_Receita!B22 -> 5597.2365
A36: Ganhos do CRM ÷ nMRR oficial do canal | B36: =Previsao_Receita!B47 -> 0.0092744271
A37: • Os dois métodos convergem: o pipeline do CRM é previsível. Mas ele explica uma fração mínima do nMRR oficial: sem fonte única de nMRR, não dá para prever a receita oficial do canal.

Sheet Drivers
A1: Drivers de conversão — taxa de conversão por característica (600 contadores)
A2: Amplitude = maior taxa − menor taxa entre as categorias com 30+ contadores. Quanto maior, mais a característica separa quem converte de quem não converte.
A3: Taxa média geral | B3: =AVERAGE(Base!$M$2:$M$601) -> 0.4
A4: Variável | B4: Categoria | C4: Contadores | D4: Convertidos | E4: Taxa | F4: Lift vs média | H4: Ranking das variáveis
A5: Nº de clientes da carteira | B5: 1. < 20 | C5: =COUNTIF(Base!$O$2:$O$601,B5) -> 194 | D5: =COUNTIFS(Base!$O$2:$O$601,B5,Base!$M$2:$M$601,1) -> 20 | E5: =IF(C5>0,D5/C5,0) -> 0.10309278 | F5: =E5/$B$3 -> 0.25773196 | H5: Variável | I5: Amplitude (p.p.) | J5: Ranking
A6: Nº de clientes da carteira | B6: 2. 20 a 49 | C6: =COUNTIF(Base!$O$2:$O$601,B6) -> 170 | D6: =COUNTIFS(Base!$O$2:$O$601,B6,Base!$M$2:$M$601,1) -> 43 | E6: =IF(C6>0,D6/C6,0) -> 0.25294118 | F6: =E6/$B$3 -> 0.63235294 | H6: Nº de clientes da carteira | I6: =(_xlfn.MAXIFS(E5:E8,C5:C8,">=30")-_xlfn.MINIFS(E5:E8,C5:C8,">=30"))*100 -> 87.628866 | J6: =RANK(I6,$I$6:$I$14) -> 3
A7: Nº de clientes da carteira | B7: 3. 50 a 149 | C7: =COUNTIF(Base!$O$2:$O$601,B7) -> 139 | D7: =COUNTIFS(Base!$O$2:$O$601,B7,Base!$M$2:$M$601,1) -> 82 | E7: =IF(C7>0,D7/C7,0) -> 0.58992806 | F7: =E7/$B$3 -> 1.4748201 | H7: Nº de funcionários | I7: =(_xlfn.MAXIFS(E10:E13,C10:C13,">=30")-_xlfn.MINIFS(E10:E13,C10:C13,">=30"))*100 -> 88.593482 | J7: =RANK(I7,$I$6:$I$14) -> 2
A8: Nº de clientes da carteira | B8: 4. 150+ | C8: =COUNTIF(Base!$O$2:$O$601,B8) -> 97 | D8: =COUNTIFS(Base!$O$2:$O$601,B8,Base!$M$2:$M$601,1) -> 95 | E8: =IF(C8>0,D8/C8,0) -> 0.97938144 | F8: =E8/$B$3 -> 2.4484536 | H8: Porte | I8: =(_xlfn.MAXIFS(E15:E18,C15:C18,">=30")-_xlfn.MINIFS(E15:E18,C15:C18,">=30"))*100 -> 93.172691 | J8: =RANK(I8,$I$6:$I$14) -> 1
H9: ERP atual | I9: =(_xlfn.MAXIFS(E20:E27,C20:C27,">=30")-_xlfn.MINIFS(E20:E27,C20:C27,">=30"))*100 -> 58.695652 | J9: =RANK(I9,$I$6:$I$14) -> 4
A10: Nº de funcionários | B10: 1. 1 a 2 | C10: =COUNTIF(Base!$P$2:$P$601,B10) -> 265 | D10: =COUNTIFS(Base!$P$2:$P$601,B10,Base!$M$2:$M$601,1) -> 23 | E10: =IF(C10>0,D10/C10,0) -> 0.086792453 | F10: =E10/$B$3 -> 0.21698113 | H10: Anos de mercado | I10: =(_xlfn.MAXIFS(E29:E31,C29:C31,">=30")-_xlfn.MINIFS(E29:E31,C29:C31,">=30"))*100 -> 34.332146 | J10: =RANK(I10,$I$6:$I$14) -> 5
A11: Nº de funcionários | B11: 2. 3 a 5 | C11: =COUNTIF(Base!$P$2:$P$601,B11) -> 84 | D11: =COUNTIFS(Base!$P$2:$P$601,B11,Base!$M$2:$M$601,1) -> 32 | E11: =IF(C11>0,D11/C11,0) -> 0.38095238 | F11: =E11/$B$3 -> 0.95238095 | H11: Região | I11: =(_xlfn.MAXIFS(E34:E38,C34:C38,">=30")-_xlfn.MINIFS(E34:E38,C34:C38,">=30"))*100 -> 22.83365 | J11: =RANK(I11,$I$6:$I$14) -> 6
A12: Nº de funcionários | B12: 3. 6 a 15 | C12: =COUNTIF(Base!$P$2:$P$601,B12) -> 141 | D12: =COUNTIFS(Base!$P$2:$P$601,B12,Base!$M$2:$M$601,1) -> 78 | E12: =IF(C12>0,D12/C12,0) -> 0.55319149 | F12: =E12/$B$3 -> 1.3829787 | H12: Segmento | I12: =(_xlfn.MAXIFS(E40:E46,C40:C46,">=30")-_xlfn.MINIFS(E40:E46,C40:C46,">=30"))*100 -> 19.230167 | J12: =RANK(I12,$I$6:$I$14) -> 7
A13: Nº de funcionários | B13: 4. 16+ | C13: =COUNTIF(Base!$P$2:$P$601,B13) -> 110 | D13: =COUNTIFS(Base!$P$2:$P$601,B13,Base!$M$2:$M$601,1) -> 107 | E13: =IF(C13>0,D13/C13,0) -> 0.97272727 | F13: =E13/$B$3 -> 2.4318182 | H13: Tem site | I13: =(_xlfn.MAXIFS(E48:E49,C48:C49,">=30")-_xlfn.MINIFS(E48:E49,C48:C49,">=30"))*100 -> 11.25871 | J13: =RANK(I13,$I$6:$I$14) -> 8
H14: LinkedIn | I14: =(_xlfn.MAXIFS(E51:E52,C51:C52,">=30")-_xlfn.MINIFS(E51:E52,C51:C52,">=30"))*100 -> 0.56690012 | J14: =RANK(I14,$I$6:$I$14) -> 9
A15: Porte | B15: Autônomo | C15: =COUNTIF(Base!$D$2:$D$601,B15) -> 249 | D15: =COUNTIFS(Base!$D$2:$D$601,B15,Base!$M$2:$M$601,1) -> 17 | E15: =IF(C15>0,D15/C15,0) -> 0.068273092 | F15: =E15/$B$3 -> 0.17068273
A16: Porte | B16: Grande Escritório | C16: =COUNTIF(Base!$D$2:$D$601,B16) -> 49 | D16: =COUNTIFS(Base!$D$2:$D$601,B16,Base!$M$2:$M$601,1) -> 49 | E16: =IF(C16>0,D16/C16,0) -> 1 | F16: =E16/$B$3 -> 2.5
A17: Porte | B17: Médio Escritório | C17: =COUNTIF(Base!$D$2:$D$601,B17) -> 83 | D17: =COUNTIFS(Base!$D$2:$D$601,B17,Base!$M$2:$M$601,1) -> 78 | E17: =IF(C17>0,D17/C17,0) -> 0.93975904 | F17: =E17/$B$3 -> 2.3493976
A18: Porte | B18: Pequeno Escritório | C18: =COUNTIF(Base!$D$2:$D$601,B18) -> 219 | D18: =COUNTIFS(Base!$D$2:$D$601,B18,Base!$M$2:$M$601,1) -> 96 | E18: =IF(C18>0,D18/C18,0) -> 0.43835616 | F18: =E18/$B$3 -> 1.0958904
A20: ERP atual | B20: Alterdata | C20: =COUNTIF(Base!$I$2:$I$601,B20) -> 46 | D20: =COUNTIFS(Base!$I$2:$I$601,B20,Base!$M$2:$M$601,1) -> 30 | E20: =IF(C20>0,D20/C20,0) -> 0.65217391 | F20: =E20/$B$3 -> 1.6304348
A21: ERP atual | B21: ContaAzul | C21: =COUNTIF(Base!$I$2:$I$601,B21) -> 19 | D21: =COUNTIFS(Base!$I$2:$I$601,B21,Base!$M$2:$M$601,1) -> 0 | E21: =IF(C21>0,D21/C21,0) -> 0 | F21: =E21/$B$3 -> 0
A22: ERP atual | B22: Domínio | C22: =COUNTIF(Base!$I$2:$I$601,B22) -> 154 | D22: =COUNTIFS(Base!$I$2:$I$601,B22,Base!$M$2:$M$601,1) -> 58 | E22: =IF(C22>0,D22/C22,0) -> 0.37662338 | F22: =E22/$B$3 -> 0.94155844
A23: ERP atual | B23: Nenhum | C23: =COUNTIF(Base!$I$2:$I$601,B23) -> 46 | D23: =COUNTIFS(Base!$I$2:$I$601,B23,Base!$M$2:$M$601,1) -> 3 | E23: =IF(C23>0,D23/C23,0) -> 0.065217391 | F23: =E23/$B$3 -> 0.16304348
A24: ERP atual | B24: Planilha | C24: =COUNTIF(Base!$I$2:$I$601,B24) -> 64 | D24: =COUNTIFS(Base!$I$2:$I$601,B24,Base!$M$2:$M$601,1) -> 10 | E24: =IF(C24>0,D24/C24,0) -> 0.15625 | F24: =E24/$B$3 -> 0.390625
A25: ERP atual | B25: Questor | C25: =COUNTIF(Base!$I$2:$I$601,B25) -> 161 | D25: =COUNTIFS(Base!$I$2:$I$601,B25,Base!$M$2:$M$601,1) -> 64 | E25: =IF(C25>0,D25/C25,0) -> 0.39751553 | F25: =E25/$B$3 -> 0.99378882
A26: ERP atual | B26: SAP | C26: =COUNTIF(Base!$I$2:$I$601,B26) -> 26 | D26: =COUNTIFS(Base!$I$2:$I$601,B26,Base!$M$2:$M$601,1) -> 26 | E26: =IF(C26>0,D26/C26,0) -> 1 | F26: =E26/$B$3 -> 2.5 | H26: ICP do canal — perfil ideal de contador (drivers → regra de ação)
A27: ERP atual | B27: Totvs | C27: =COUNTIF(Base!$I$2:$I$601,B27) -> 84 | D27: =COUNTIFS(Base!$I$2:$I$601,B27,Base!$M$2:$M$601,1) -> 49 | E27: =IF(C27>0,D27/C27,0) -> 0.58333333 | F27: =E27/$B$3 -> 1.4583333 | H27: Regra: carteira com 50+ clientes E 6+ funcionários E ERP de mercado (não Nenhum/Planilha/ContaAzul).
H28: Grupo | I28: Contadores | J28: % converteu_omie | K28: Cliente Ativo (status_omie) | L28: Endereçáveis (regra 1a) | M28: Carteira endereçável
A29: Anos de mercado | B29: 1. < 8 anos | C29: =COUNTIF(Base!$N$2:$N$601,B29) -> 152 | D29: =COUNTIFS(Base!$N$2:$N$601,B29,Base!$M$2:$M$601,1) -> 34 | E29: =IF(C29>0,D29/C29,0) -> 0.22368421 | F29: =E29/$B$3 -> 0.55921053 | H29: ICP | I29: =COUNTIF(Base!$R$2:$R$601,1) -> 185 | J29: =AVERAGEIF(Base!$R$2:$R$601,1,Base!$M$2:$M$601) -> 0.83783784 | K29: =COUNTIFS(Base!$R$2:$R$601,1,Base!$L$2:$L$601,"Cliente Ativo") -> 26 | L29: =COUNTIFS(Base!$R$2:$R$601,1,Base!$S$2:$S$601,1) -> 24 | M29: =SUMIFS(Base!$G$2:$G$601,Base!$R$2:$R$601,1,Base!$S$2:$S$601,1) -> 1805
A30: Anos de mercado | B30: 2. 8 a 15 anos | C30: =COUNTIF(Base!$N$2:$N$601,B30) -> 139 | D30: =COUNTIFS(Base!$N$2:$N$601,B30,Base!$M$2:$M$601,1) -> 31 | E30: =IF(C30>0,D30/C30,0) -> 0.22302158 | F30: =E30/$B$3 -> 0.55755396 | H30: Fora do ICP | I30: =COUNTIF(Base!$R$2:$R$601,0) -> 415 | J30: =AVERAGEIF(Base!$R$2:$R$601,0,Base!$M$2:$M$601) -> 0.20481928 | K30: =COUNTIFS(Base!$R$2:$R$601,0,Base!$L$2:$L$601,"Cliente Ativo") -> 69 | L30: =COUNTIFS(Base!$R$2:$R$601,0,Base!$S$2:$S$601,1) -> 279 | M30: =SUMIFS(Base!$G$2:$G$601,Base!$R$2:$R$601,0,Base!$S$2:$S$601,1) -> 6396
A31: Anos de mercado | B31: 3. 16+ anos | C31: =COUNTIF(Base!$N$2:$N$601,B31) -> 309 | D31: =COUNTIFS(Base!$N$2:$N$601,B31,Base!$M$2:$M$601,1) -> 175 | E31: =IF(C31>0,D31/C31,0) -> 0.56634304 | F31: =E31/$B$3 -> 1.4158576 | H31: Lift do ICP vs média (taxa do ICP ÷ média) | J31: =J29/$B$3 -> 2.0945946
H32: Lift do ICP vs fora do ICP | J32: =J29/J30 -> 4.09062
A33: Fora do top 5 (efeito pequeno) | H33: % da carteira endereçável no ICP | J33: =M29/(M29+M30) -> 0.22009511
A34: Região | B34: Centro-Oeste | C34: =COUNTIF(Base!$C$2:$C$601,B34) -> 87 | D34: =COUNTIFS(Base!$C$2:$C$601,B34,Base!$M$2:$M$601,1) -> 38 | E34: =IF(C34>0,D34/C34,0) -> 0.43678161 | F34: =E34/$B$3 -> 1.091954 | H34: Atenção: no pipeline real o win rate do ICP NÃO é maior (aba Como_Avaliar). O ICP é uma hipótese a validar com piloto + grupo de controle.
A35: Região | B35: Nordeste | C35: =COUNTIF(Base!$C$2:$C$601,B35) -> 93 | D35: =COUNTIFS(Base!$C$2:$C$601,B35,Base!$M$2:$M$601,1) -> 28 | E35: =IF(C35>0,D35/C35,0) -> 0.30107527 | F35: =E35/$B$3 -> 0.75268817
A36: Região | B36: Norte | C36: =COUNTIF(Base!$C$2:$C$601,B36) -> 27 | D36: =COUNTIFS(Base!$C$2:$C$601,B36,Base!$M$2:$M$601,1) -> 9 | E36: =IF(C36>0,D36/C36,0) -> 0.33333333 | F36: =E36/$B$3 -> 0.83333333
A37: Região | B37: Sudeste | C37: =COUNTIF(Base!$C$2:$C$601,B37) -> 291 | D37: =COUNTIFS(Base!$C$2:$C$601,B37,Base!$M$2:$M$601,1) -> 111 | E37: =IF(C37>0,D37/C37,0) -> 0.3814433 | F37: =E37/$B$3 -> 0.95360825
A38: Região | B38: Sul | C38: =COUNTIF(Base!$C$2:$C$601,B38) -> 102 | D38: =COUNTIFS(Base!$C$2:$C$601,B38,Base!$M$2:$M$601,1) -> 54 | E38: =IF(C38>0,D38/C38,0) -> 0.52941176 | F38: =E38/$B$3 -> 1.3235294
A40: Segmento | B40: Agronegócio | C40: =COUNTIF(Base!$E$2:$E$601,B40) -> 93 | D40: =COUNTIFS(Base!$E$2:$E$601,B40,Base!$M$2:$M$601,1) -> 38 | E40: =IF(C40>0,D40/C40,0) -> 0.40860215 | F40: =E40/$B$3 -> 1.0215054
A41: Segmento | B41: Construção Civil | C41: =COUNTIF(Base!$E$2:$E$601,B41) -> 86 | D41: =COUNTIFS(Base!$E$2:$E$601,B41,Base!$M$2:$M$601,1) -> 34 | E41: =IF(C41>0,D41/C41,0) -> 0.39534884 | F41: =E41/$B$3 -> 0.98837209
A42: Segmento | B42: Indústria | C42: =COUNTIF(Base!$E$2:$E$601,B42) -> 85 | D42: =COUNTIFS(Base!$E$2:$E$601,B42,Base!$M$2:$M$601,1) -> 35 | E42: =IF(C42>0,D42/C42,0) -> 0.41176471 | F42: =E42/$B$3 -> 1.0294118
...

Sheet Como_Avaliar
A1: Como avaliar se a abordagem está funcionando
A2: Em duas etapas: (1) validação na base — o score ordena quem converte e o topo fecha mais no pipeline real?; (2) piloto de 90 dias com grupo de controle — priorizar o topo gera mais Ganhos e mais nMRR por EC?
A4: Métrica | B4: O que mede | C4: Hoje | D4: Meta | E4: Etapa
A5: Conversão por faixa de propensão (Alta · Média · Baixa) | B5: Se o score ordena quem converte (target) | C5: =FIXED(C19*100,0)&"% · "&FIXED(C20*100,0)&"% · "&FIXED(C21*100,0)&"%" -> 91% · 29% · 3% | D5: Alta > Média > Baixa | E5: 1. Base
A6: Captura: % dos convertidos no top 30% | B6: Quanto da conversão está no topo | C6: =SUMIF(Base!$AB$2:$AB$601,"Alta",Base!$M$2:$M$601)/SUM(Base!$M$2:$M$601) -> 0.69166667 | D6: Maior que os 30% da base que o topo representa | E6: 1. Base
A7: Win rate real: faixa Alta × demais | B7: Se o topo fecha mais de verdade (Ganho ÷ Ganho + Perdido) | C7: =FIXED(G19*100,0)&"% × "&FIXED(G22*100,0)&"%" -> 60% × 65% | D7: Alta acima das demais | E7: 1. Base e 2. Piloto
A8: Win rate: piloto × controle | B8: Se priorizar o topo gera mais Ganhos | C8: a medir no piloto | D8: Piloto acima do controle | E8: 2. Piloto
A9: nMRR por EC: piloto × controle | B9: Se o ganho de conversão vira receita | C9: a medir no piloto | D9: Piloto acima do controle | E9: 2. Piloto
A10: Ciclo médio do Ganho (dias): faixa Alta × demais | B10: Se priorizar não alonga a venda | C10: =FIXED(H19,0)&" × "&FIXED(H22,0)&" dias" -> 36 × 48 dias | D10: Alta ≤ demais | E10: 1. Base e 2. Piloto
A12: Regra de decisão: se o piloto superar o controle, a priorização pelo score vira processo; senão, o perfil é revisto.
A14: Cortes do score (faixas de propensão dos 600 contadores)
A15: Faixa Alta: score a partir do percentil 70 (top 30%) | B15: =_xlfn.PERCENTILE.INC(Base!$AA$2:$AA$601,0.7) -> 0.47883304
A16: Faixa Média: a partir do percentil 30 | B16: =_xlfn.PERCENTILE.INC(Base!$AA$2:$AA$601,0.3) -> 0.24022495
A18: Faixa de propensão | B18: Contadores | C18: % converteu_omie (target) | D18: Lift vs média | E18: Leads com desfecho (Ganho+Perdido) | F18: Leads Ganhos | G18: Win rate real | H18: Ciclo médio do Ganho (dias)
A19: Alta | B19: =COUNTIF(Base!$AB$2:$AB$601,A19) -> 183 | C19: =AVERAGEIF(Base!$AB$2:$AB$601,A19,Base!$M$2:$M$601) -> 0.90710383 | D19: =C19/Drivers!$B$3 -> 2.2677596 | E19: =COUNTIFS(Leads!$N$2:$N$351,A19,Leads!$J$2:$J$351,1) -> 30 | F19: =COUNTIFS(Leads!$N$2:$N$351,A19,Leads!$K$2:$K$351,1) -> 18 | G19: =IF(E19>0,F19/E19,0) -> 0.6 | H19: =AVERAGEIFS(Leads!$O$2:$O$351,Leads!$N$2:$N$351,A19,Leads!$K$2:$K$351,1) -> 35.666667
A20: Média | B20: =COUNTIF(Base!$AB$2:$AB$601,A20) -> 241 | C20: =AVERAGEIF(Base!$AB$2:$AB$601,A20,Base!$M$2:$M$601) -> 0.28630705 | D20: =C20/Drivers!$B$3 -> 0.71576763 | E20: =COUNTIFS(Leads!$N$2:$N$351,A20,Leads!$J$2:$J$351,1) -> 51 | F20: =COUNTIFS(Leads!$N$2:$N$351,A20,Leads!$K$2:$K$351,1) -> 34 | G20: =IF(E20>0,F20/E20,0) -> 0.66666667 | H20: =AVERAGEIFS(Leads!$O$2:$O$351,Leads!$N$2:$N$351,A20,Leads!$K$2:$K$351,1) -> 44.235294
A21: Baixa | B21: =COUNTIF(Base!$AB$2:$AB$601,A21) -> 176 | C21: =AVERAGEIF(Base!$AB$2:$AB$601,A21,Base!$M$2:$M$601) -> 0.028409091 | D21: =C21/Drivers!$B$3 -> 0.071022727 | E21: =COUNTIFS(Leads!$N$2:$N$351,A21,Leads!$J$2:$J$351,1) -> 33 | F21: =COUNTIFS(Leads!$N$2:$N$351,A21,Leads!$K$2:$K$351,1) -> 21 | G21: =IF(E21>0,F21/E21,0) -> 0.63636364 | H21: =AVERAGEIFS(Leads!$O$2:$O$351,Leads!$N$2:$N$351,A21,Leads!$K$2:$K$351,1) -> 53.095238
A22: Demais (Média + Baixa) | B22: =B20+B21 -> 417 | C22: =(C20*B20+C21*B21)/B22 -> 0.17745803 | D22: =C22/Drivers!$B$3 -> 0.44364508 | E22: =E20+E21 -> 84 | F22: =F20+F21 -> 55 | G22: =IF(E22>0,F22/E22,0) -> 0.6547619 | H22: =AVERAGEIFS(Leads!$O$2:$O$351,Leads!$N$2:$N$351,"<>Alta",Leads!$K$2:$K$351,1) -> 47.618182
A24: O target reflete o fechamento real? (por porte)
A25: Porte | B25: Contadores | C25: % converteu_omie (target) | D25: Leads com desfecho (Ganho+Perdido) | E25: Leads Ganhos | F25: Win rate real | G25: Contratos em clientes_ativos
A26: Autônomo | B26: =COUNTIF(Base!$D$2:$D$601,A26) -> 249 | C26: =AVERAGEIF(Base!$D$2:$D$601,A26,Base!$M$2:$M$601) -> 0.068273092 | D26: =COUNTIFS(Leads!$G$2:$G$351,A26,Leads!$J$2:$J$351,1) -> 52 | E26: =COUNTIFS(Leads!$G$2:$G$351,A26,Leads!$K$2:$K$351,1) -> 35 | F26: =IF(D26>0,E26/D26,0) -> 0.67307692 | G26: =COUNTIF(Clientes!$F$2:$F$74,A26) -> 35
A27: Pequeno Escritório | B27: =COUNTIF(Base!$D$2:$D$601,A27) -> 219 | C27: =AVERAGEIF(Base!$D$2:$D$601,A27,Base!$M$2:$M$601) -> 0.43835616 | D27: =COUNTIFS(Leads!$G$2:$G$351,A27,Leads!$J$2:$J$351,1) -> 42 | E27: =COUNTIFS(Leads!$G$2:$G$351,A27,Leads!$K$2:$K$351,1) -> 27 | F27: =IF(D27>0,E27/D27,0) -> 0.64285714 | G27: =COUNTIF(Clientes!$F$2:$F$74,A27) -> 27
A28: Médio Escritório | B28: =COUNTIF(Base!$D$2:$D$601,A28) -> 83 | C28: =AVERAGEIF(Base!$D$2:$D$601,A28,Base!$M$2:$M$601) -> 0.93975904 | D28: =COUNTIFS(Leads!$G$2:$G$351,A28,Leads!$J$2:$J$351,1) -> 13 | E28: =COUNTIFS(Leads!$G$2:$G$351,A28,Leads!$K$2:$K$351,1) -> 6 | F28: =IF(D28>0,E28/D28,0) -> 0.46153846 | G28: =COUNTIF(Clientes!$F$2:$F$74,A28) -> 6
A29: Grande Escritório | B29: =COUNTIF(Base!$D$2:$D$601,A29) -> 49 | C29: =AVERAGEIF(Base!$D$2:$D$601,A29,Base!$M$2:$M$601) -> 1 | D29: =COUNTIFS(Leads!$G$2:$G$351,A29,Leads!$J$2:$J$351,1) -> 7 | E29: =COUNTIFS(Leads!$G$2:$G$351,A29,Leads!$K$2:$K$351,1) -> 5 | F29: =IF(D29>0,E29/D29,0) -> 0.71428571 | G29: =COUNTIF(Clientes!$F$2:$F$74,A29) -> 5
A30: Total | B30: =SUM(B26:B29) -> 600 | C30: =AVERAGE(Base!$M$2:$M$601) -> 0.4 | D30: =SUM(D26:D29) -> 114 | E30: =SUM(E26:E29) -> 73 | F30: =IF(D30>0,E30/D30,0) -> 0.64035088 | G30: =SUM(G26:G29) -> 73
A32: Leitura
A33: • Etapa 1: pelo target o score ordena muito bem (a faixa Alta converte ~30x a Baixa), mas o target vaza do score_potencial_latente, dominado por tamanho e ERP: a separação é alta por construção.
A34: • No pipeline real o topo fecha mais rápido, mas não fecha mais: só a etapa 2 (piloto com controle) prova se priorizar o score gera receita.

Sheet Impacto_nMRR
A1: Extra — nMRR incremental ao priorizar quem tem maior propensão
A2: Lógica: parte da capacidade mensal dos ECs vai para o topo da propensão (top 30% do score). O ganho de conversão vem do lift do topo (taxa do top 30% ÷ média), descontado pelo fator de realização. O resultado principal é o UPLIFT %.
A4: Premissa | B4: Conservador | C4: Base | D4: Otimista | E4: Fonte / racional
A5: ECs na rede | B5: 44 | C5: =B5 -> 44 | D5: =B5 -> 44 | E5: Soma de num_executivos (aba franquias)
A6: Leads trabalhados por EC/mês | B6: 16.5 | C6: =B6 -> 16.5 | D6: =B6 -> 16.5 | E6: Média de leads_trabalhados (execucao_comercial)
A7: Taxa atual lead trabalhado → fechamento | B7: 0.0398 | C7: =B7 -> 0.0398 | D7: =B7 -> 0.0398 | E7: Σ fechamentos / Σ leads_trabalhados (execucao_comercial)
A8: % da capacidade redirecionada ao topo da propensão | B8: 0.3 | C8: 0.5 | D8: 0.6 | E8: Decisão de gestão (premissa)
A9: Lift do topo da propensão (top 30% ÷ média) | B9: =Como_Avaliar!$D$19 -> 2.2677596 | C9: =B9 -> 2.2677596 | D9: =B9 -> 2.2677596 | E9: Aba Como_Avaliar — descritivo, sem modelo
A10: Fator de realização do lift | B10: 0.25 | C10: 0.4 | D10: 0.6 | E10: Fração do lift que vira Ganho real (o target diverge do real — aba Como_Avaliar)
A11: Ticket MRR por novo cliente (R$) | B11: 590 | C11: =AVERAGE(Clientes!$D$2:$D$74) -> 1025.65 | D11: =AVERAGE(Clientes!$D$2:$D$74) -> 1025.65 | E11: Conservador: nMRR por fechamento da execução. Base/Otimista: mrr_inicial médio (clientes_ativos)
A12: Haircut de churn | B12: =COUNTIF(Clientes!$C$2:$C$74,"Churned")/COUNTA(Clientes!$A$2:$A$74) -> 0.20547945 | C12: =B12 -> 0.20547945 | D12: =B12 -> 0.20547945 | E12: Contratos Churned / total (vida do contrato) — desconto fixo, conservador
A13: nMRR oficial das 9 franquias abaixo da meta (R$/mês) | B13: 124000 | C13: =B13 -> 124000 | D13: =B13 -> 124000 | E13: franquias.realizado_nmrr_mes onde realizado < meta
A16: Cálculo | B16: Conservador | C16: Base | D16: Otimista | E16: Fórmula
A17: Leads trabalhados/mês (rede) | B17: =B5*B6 -> 726 | C17: =C5*C6 -> 726 | D17: =D5*D6 -> 726 | E17: ECs × leads por EC
A18: Leads redirecionados ao topo da propensão | B18: =B17*B8 -> 217.8 | C18: =C17*C8 -> 363 | D18: =D17*D8 -> 435.6 | E18: capacidade × % redirecionada
A19: Conversão nova nesses leads | B19: =B7*(1+(B9-1)*B10) -> 0.052414208 | C19: =C7*(1+(C9-1)*C10) -> 0.059982732 | D19: =D7*(1+(D9-1)*D10) -> 0.070074098 | E19: taxa atual × (1 + (lift − 1) × fator)
A20: Fechamentos incrementais/mês | B20: =B18*(B19-B7) -> 2.7473744 | C20: =C18*(C19-C7) -> 7.3263318 | D20: =D18*(D19-D7) -> 13.187397 | E20: leads redirecionados × ganho de conversão
A21: nMRR incremental/mês — escala da execução | B21: =B20*B11*(1-B12) -> 1287.8788 | C21: =C20*C11*(1-C12) -> 5970.2278 | D21: =D20*D11*(1-D12) -> 10746.41 | E21: fechamentos × ticket × (1 − churn)
A22: nMRR atual/mês — mesma escala | B22: =B17*B7*B11*(1-B12) -> 13544.932 | C22: =C17*C7*C11*(1-C12) -> 23546.373 | D22: =D17*D7*D11*(1-D12) -> 23546.373 | E22: leads × conversão × ticket × (1 − churn)
A23: UPLIFT no nMRR do canal | B23: =B21/B22 -> 0.095081967 | C23: =C21/C22 -> 0.25355191 | D23: =D21/D22 -> 0.45639344 | E23: incremental ÷ atual (independe da escala de receita)
A24: nMRR incremental/mês — escala oficial (franquias abaixo da meta) | B24: =B23*B13 -> 11790.164 | C24: =C23*C13 -> 31440.437 | D24: =D23*D13 -> 56592.787 | E24: uplift × realizado oficial dessas franquias
A27: Premissas assumidas
A28: • Capacidade dos ECs constante; o redirecionamento não muda o ticket nem o ciclo; sem custo adicional de aquisição.
A29: • O lift do topo foi medido no target converteu_omie; só uma fração (fator de realização) vira Ganho real.
A30: • Teste de estresse: com fator de realização = 0 (como o pipeline real sugere hoje), o uplift é zero — por isso o piloto.
A31: • O nMRR da execução é 10 a 27x menor que o oficial das franquias; por isso o uplift % é o número principal (franquias.realizado_nmrr_mes contra execucao_comercial.nmrr_gerado).

Sheet Previsao_Receita
A1: Previsibilidade de receita: quanto o pipeline atual deve gerar no próximo trimestre
A2: Dois métodos independentes, só com dados da base: (1) pipeline aberto ponderado pela chance de fechar de cada estágio; (2) run-rate histórico de Ganhos do CRM. Janela de 90 dias: nenhum Ganho da base fechou depois de 89 dias.
A4: 1. Chance de fechar por estágio (funil de execucao_comercial, 2024)
A5: Etapa do funil | B5: Volume | C5: Taxa da etapa
A6: Leads trabalhados | B6: 8699
A7: Reuniões realizadas | B7: 3617 | C7: =B7/B6 -> 0.41579492 | D7: Lead → reunião
A8: Propostas enviadas | B8: 1797 | C8: =B8/B7 -> 0.49682057 | D8: Reunião → proposta
A9: Fechamentos | B9: 346 | C9: =B9/B8 -> 0.19254313 | D9: Proposta → fechamento
A11: 2. Método 1: pipeline aberto ponderado (leads abertos há até 90 dias)
A12: Estágio do lead | B12: Leads abertos até 90 dias | C12: Chance de fechar | D12: Ganhos esperados | E12: Leads parados (> 90 dias): chance 0 | F12: De onde vem a chance
A13: Proposta Enviada | B13: =COUNTIFS(Leads!$D$2:$D$351,A13,Leads!$O$2:$O$351,"<=90") -> 15 | C13: =C9 -> 0.19254313 | D13: =B13*C13 -> 2.8881469 | E13: =COUNTIFS(Leads!$D$2:$D$351,A13,Leads!$O$2:$O$351,">90") -> 33 | F13: Proposta → fechamento
A14: Reunião Agendada | B14: =COUNTIFS(Leads!$D$2:$D$351,A14,Leads!$O$2:$O$351,"<=90") -> 15 | C14: =C8*C9 -> 0.095659386 | D14: =B14*C14 -> 1.4348908 | E14: =COUNTIFS(Leads!$D$2:$D$351,A14,Leads!$O$2:$O$351,">90") -> 26 | F14: Reunião → proposta → fechamento
A15: Em Contato | B15: =COUNTIFS(Leads!$D$2:$D$351,A15,Leads!$O$2:$O$351,"<=90") -> 31 | C15: =C7*C8*C9 -> 0.039774687 | D15: =B15*C15 -> 1.2330153 | E15: =COUNTIFS(Leads!$D$2:$D$351,A15,Leads!$O$2:$O$351,">90") -> 38 | F15: Lead → reunião → proposta → fechamento
A16: Novo | B16: =COUNTIFS(Leads!$D$2:$D$351,A16,Leads!$O$2:$O$351,"<=90") -> 33 | C16: =C7*C8*C9 -> 0.039774687 | D16: =B16*C16 -> 1.3125647 | E16: =COUNTIFS(Leads!$D$2:$D$351,A16,Leads!$O$2:$O$351,">90") -> 24 | F16: Lead → reunião → proposta → fechamento
A17: Sem Resposta | B17: =COUNTIFS(Leads!$D$2:$D$351,A17,Leads!$O$2:$O$351,"<=90") -> 9 | C17: 0 | D17: =B17*C17 -> 0 | E17: =COUNTIFS(Leads!$D$2:$D$351,A17,Leads!$O$2:$O$351,">90") -> 12 | F17: Fora do funil: o contador não respondeu
A18: Total | B18: =SUM(B13:B17) -> 103 | D18: =SUM(D13:D17) -> 6.8686177 | E18: =SUM(E13:E17) -> 133
A20: Ticket médio do Ganho (R$) | B20: =AVERAGEIF(Leads!$D$2:$D$351,"Ganho",Leads!$E$2:$E$351) -> 1025.65
A21: Churn dos contratos | B21: =COUNTIF(Clientes!$C$2:$C$74,"Churned")/COUNTA(Clientes!$A$2:$A$74) -> 0.20547945
A22: nMRR esperado do pipeline no trimestre (R$, escala do CRM) | B22: =D18*B20*(1-B21) -> 5597.2365
A24: 3. Método 2: run-rate histórico de Ganhos (CRM)
A25: Primeiro Ganho | B25: =MIN(Leads!$P$2:$P$351) -> 45304
A26: Último Ganho | B26: =MAX(Leads!$P$2:$P$351) -> 46088
A27: Meses de histórico | B27: =(YEAR(B26)-YEAR(B25))*12+MONTH(B26)-MONTH(B25)+1 -> 27
A28: Ganhos no período | B28: =COUNTIF(Leads!$D$2:$D$351,"Ganho") -> 73
A29: Ganhos por trimestre (run-rate) | B29: =B28/B27*3 -> 8.1111111
A30: Menor e maior trimestre fechado | B30: =MIN(D33:D40)&" a "&MAX(D33:D40) -> 3 a 12
A32: Trimestre | B32: Início | C32: Fim | D32: Ganhos
A33: 2024 T1 | B33: =DATE(2024,1,1) -> 45292 | C33: =EOMONTH(B33,2) -> 45382 | D33: =COUNTIFS(Leads!$D$2:$D$351,"Ganho",Leads!$P$2:$P$351,">="&B33,Leads!$P$2:$P$351,"<="&C33) -> 3
A34: 2024 T2 | B34: =DATE(2024,4,1) -> 45383 | C34: =EOMONTH(B34,2) -> 45473 | D34: =COUNTIFS(Leads!$D$2:$D$351,"Ganho",Leads!$P$2:$P$351,">="&B34,Leads!$P$2:$P$351,"<="&C34) -> 11
A35: 2024 T3 | B35: =DATE(2024,7,1) -> 45474 | C35: =EOMONTH(B35,2) -> 45565 | D35: =COUNTIFS(Leads!$D$2:$D$351,"Ganho",Leads!$P$2:$P$351,">="&B35,Leads!$P$2:$P$351,"<="&C35) -> 7
A36: 2024 T4 | B36: =DATE(2024,10,1) -> 45566 | C36: =EOMONTH(B36,2) -> 45657 | D36: =COUNTIFS(Leads!$D$2:$D$351,"Ganho",Leads!$P$2:$P$351,">="&B36,Leads!$P$2:$P$351,"<="&C36) -> 7
A37: 2025 T1 | B37: =DATE(2025,1,1) -> 45658 | C37: =EOMONTH(B37,2) -> 45747 | D37: =COUNTIFS(Leads!$D$2:$D$351,"Ganho",Leads!$P$2:$P$351,">="&B37,Leads!$P$2:$P$351,"<="&C37) -> 5
A38: 2025 T2 | B38: =DATE(2025,4,1) -> 45748 | C38: =EOMONTH(B38,2) -> 45838 | D38: =COUNTIFS(Leads!$D$2:$D$351,"Ganho",Leads!$P$2:$P$351,">="&B38,Leads!$P$2:$P$351,"<="&C38) -> 10
A39: 2025 T3 | B39: =DATE(2025,7,1) -> 45839 | C39: =EOMONTH(B39,2) -> 45930 | D39: =COUNTIFS(Leads!$D$2:$D$351,"Ganho",Leads!$P$2:$P$351,">="&B39,Leads!$P$2:$P$351,"<="&C39) -> 12
A40: 2025 T4 | B40: =DATE(2025,10,1) -> 45931 | C40: =EOMONTH(B40,2) -> 46022 | D40: =COUNTIFS(Leads!$D$2:$D$351,"Ganho",Leads!$P$2:$P$351,">="&B40,Leads!$P$2:$P$351,"<="&C40) -> 10
A41: 2026 T1 (parcial, até 07/03) | B41: =DATE(2026,1,1) -> 46023 | C41: =EOMONTH(B41,2) -> 46112 | D41: =COUNTIFS(Leads!$D$2:$D$351,"Ganho",Leads!$P$2:$P$351,">="&B41,Leads!$P$2:$P$351,"<="&C41) -> 8
A44: 4. Lacuna de previsibilidade e alavanca
A45: nMRR de Ganhos do CRM por mês (R$) | B45: =SUMIF(Leads!$D$2:$D$351,"Ganho",Leads!$E$2:$E$351)/B27 -> 2773.0537
A46: nMRR oficial da rede por mês (R$, aba franquias) | B46: 299000
A47: CRM ÷ oficial | B47: =B45/B46 -> 0.0092744271
...

Sheet Base
A1: id_contador | B1: estado | C1: regiao | D1: porte | E1: segmento_principal | F1: anos_mercado | G1: num_clientes_ativos | H1: num_funcionarios | I1: erp_atual | J1: tem_site | K1: presenca_linkedin | L1: status_omie | M1: converteu_omie | N1: faixa_anos | O1: faixa_clientes | P1: faixa_funcionarios | Q1: sem_erp | R1: icp | S1: enderecavel (regra 1a) | T1: score Fit + Engajamento (1c, 1 a 5) | U1: tier de prioridade (1c) | V1: taxa do porte | W1: taxa da faixa de funcionários | X1: taxa da faixa de clientes | Y1: taxa do ERP | Z1: taxa da faixa de anos | AA1: PROPENSÃO (média das 5 taxas) | AB1: faixa de propensão
A2: CTD00001 | B2: RS | C2: Sul | D2: Pequeno Escritório | E2: Construção Civil | F2: 7 | G2: 32 | H2: 10 | I2: Questor | J2: Sim | K2: Sim | L2: Prospect | M2: 1 | N2: =IF(F2<8,"1. < 8 anos",IF(F2<16,"2. 8 a 15 anos","3. 16+ anos")) -> 1. < 8 anos | O2: =IF(G2<20,"1. < 20",IF(G2<50,"2. 20 a 49",IF(G2<150,"3. 50 a 149","4. 150+"))) -> 2. 20 a 49 | P2: =IF(H2<=2,"1. 1 a 2",IF(H2<=5,"2. 3 a 5",IF(H2<=15,"3. 6 a 15","4. 16+"))) -> 3. 6 a 15 | Q2: =IF(OR(I2="Nenhum",I2="Planilha",I2="ContaAzul"),1,0) -> 0 | R2: =IF(AND(G2>=50,H2>=6,Q2=0),1,0) -> 0 | S2: =IF(AND(L2<>"Cliente Ativo",M2=0),1,0) -> 0 | V2: =AVERAGEIF($D$2:$D$601,D2,$M$2:$M$601) -> 0.43835616 | W2: =AVERAGEIF($P$2:$P$601,P2,$M$2:$M$601) -> 0.55319149 | X2: =AVERAGEIF($O$2:$O$601,O2,$M$2:$M$601) -> 0.25294118 | Y2: =AVERAGEIF($I$2:$I$601,I2,$M$2:$M$601) -> 0.39751553 | Z2: =AVERAGEIF($N$2:$N$601,N2,$M$2:$M$601) -> 0.22368421 | AA2: =ROUND(AVERAGE(V2:Z2),10) -> 0.37313771 | AB2: =IF(AA2>=Como_Avaliar!$B$15,"Alta",IF(AA2>=Como_Avaliar!$B$16,"Média","Baixa")) -> Média
A3: CTD00002 | B3: SP | C3: Sudeste | D3: Médio Escritório | E3: Saúde | F3: 20 | G3: 143 | H3: 20 | I3: Domínio | J3: Não | K3: Sim | L3: Prospect | M3: 1 | N3: =IF(F3<8,"1. < 8 anos",IF(F3<16,"2. 8 a 15 anos","3. 16+ anos")) -> 3. 16+ anos | O3: =IF(G3<20,"1. < 20",IF(G3<50,"2. 20 a 49",IF(G3<150,"3. 50 a 149","4. 150+"))) -> 3. 50 a 149 | P3: =IF(H3<=2,"1. 1 a 2",IF(H3<=5,"2. 3 a 5",IF(H3<=15,"3. 6 a 15","4. 16+"))) -> 4. 16+ | Q3: =IF(OR(I3="Nenhum",I3="Planilha",I3="ContaAzul"),1,0) -> 0 | R3: =IF(AND(G3>=50,H3>=6,Q3=0),1,0) -> 1 | S3: =IF(AND(L3<>"Cliente Ativo",M3=0),1,0) -> 0 | V3: =AVERAGEIF($D$2:$D$601,D3,$M$2:$M$601) -> 0.93975904 | W3: =AVERAGEIF($P$2:$P$601,P3,$M$2:$M$601) -> 0.97272727 | X3: =AVERAGEIF($O$2:$O$601,O3,$M$2:$M$601) -> 0.58992806 | Y3: =AVERAGEIF($I$2:$I$601,I3,$M$2:$M$601) -> 0.37662338 | Z3: =AVERAGEIF($N$2:$N$601,N3,$M$2:$M$601) -> 0.56634304 | AA3: =ROUND(AVERAGE(V3:Z3),10) -> 0.68907616 | AB3: =IF(AA3>=Como_Avaliar!$B$15,"Alta",IF(AA3>=Como_Avaliar!$B$16,"Média","Baixa")) -> Alta
A4: CTD00003 | B4: RJ | C4: Sudeste | D4: Grande Escritório | E4: Construção Civil | F4: 29 | G4: 526 | H4: 80 | I4: SAP | J4: Sim | K4: Não | L4: Lead Frio | M4: 1 | N4: =IF(F4<8,"1. < 8 anos",IF(F4<16,"2. 8 a 15 anos","3. 16+ anos")) -> 3. 16+ anos | O4: =IF(G4<20,"1. < 20",IF(G4<50,"2. 20 a 49",IF(G4<150,"3. 50 a 149","4. 150+"))) -> 4. 150+ | P4: =IF(H4<=2,"1. 1 a 2",IF(H4<=5,"2. 3 a 5",IF(H4<=15,"3. 6 a 15","4. 16+"))) -> 4. 16+ | Q4: =IF(OR(I4="Nenhum",I4="Planilha",I4="ContaAzul"),1,0) -> 0 | R4: =IF(AND(G4>=50,H4>=6,Q4=0),1,0) -> 1 | S4: =IF(AND(L4<>"Cliente Ativo",M4=0),1,0) -> 0 | V4: =AVERAGEIF($D$2:$D$601,D4,$M$2:$M$601) -> 1 | W4: =AVERAGEIF($P$2:$P$601,P4,$M$2:$M$601) -> 0.97272727 | X4: =AVERAGEIF($O$2:$O$601,O4,$M$2:$M$601) -> 0.97938144 | Y4: =AVERAGEIF($I$2:$I$601,I4,$M$2:$M$601) -> 1 | Z4: =AVERAGEIF($N$2:$N$601,N4,$M$2:$M$601) -> 0.56634304 | AA4: =ROUND(AVERAGE(V4:Z4),10) -> 0.90369035 | AB4: =IF(AA4>=Como_Avaliar!$B$15,"Alta",IF(AA4>=Como_Avaliar!$B$16,"Média","Baixa")) -> Alta
A5: CTD00004 | B5: RJ | C5: Sudeste | D5: Pequeno Escritório | E5: Tecnologia | F5: 15 | G5: 35 | H5: 4 | I5: Questor | J5: Não | K5: Sim | L5: Prospect | M5: 0 | N5: =IF(F5<8,"1. < 8 anos",IF(F5<16,"2. 8 a 15 anos","3. 16+ anos")) -> 2. 8 a 15 anos | O5: =IF(G5<20,"1. < 20",IF(G5<50,"2. 20 a 49",IF(G5<150,"3. 50 a 149","4. 150+"))) -> 2. 20 a 49 | P5: =IF(H5<=2,"1. 1 a 2",IF(H5<=5,"2. 3 a 5",IF(H5<=15,"3. 6 a 15","4. 16+"))) -> 2. 3 a 5 | Q5: =IF(OR(I5="Nenhum",I5="Planilha",I5="ContaAzul"),1,0) -> 0 | R5: =IF(AND(G5>=50,H5>=6,Q5=0),1,0) -> 0 | S5: =IF(AND(L5<>"Cliente Ativo",M5=0),1,0) -> 1 | T5: 4 | U5: Alta | V5: =AVERAGEIF($D$2:$D$601,D5,$M$2:$M$601) -> 0.43835616 | W5: =AVERAGEIF($P$2:$P$601,P5,$M$2:$M$601) -> 0.38095238 | X5: =AVERAGEIF($O$2:$O$601,O5,$M$2:$M$601) -> 0.25294118 | Y5: =AVERAGEIF($I$2:$I$601,I5,$M$2:$M$601) -> 0.39751553 | Z5: =AVERAGEIF($N$2:$N$601,N5,$M$2:$M$601) -> 0.22302158 | AA5: =ROUND(AVERAGE(V5:Z5),10) -> 0.33855737 | AB5: =IF(AA5>=Como_Avaliar!$B$15,"Alta",IF(AA5>=Como_Avaliar!$B$16,"Média","Baixa")) -> Média
A6: CTD00005 | B6: MT | C6: Centro-Oeste | D6: Médio Escritório | E6: Construção Civil | F6: 11 | G6: 160 | H6: 29 | I6: Domínio | J6: Sim | K6: Não | L6: Churned | M6: 0 | N6: =IF(F6<8,"1. < 8 anos",IF(F6<16,"2. 8 a 15 anos","3. 16+ anos")) -> 2. 8 a 15 anos | O6: =IF(G6<20,"1. < 20",IF(G6<50,"2. 20 a 49",IF(G6<150,"3. 50 a 149","4. 150+"))) -> 4. 150+ | P6: =IF(H6<=2,"1. 1 a 2",IF(H6<=5,"2. 3 a 5",IF(H6<=15,"3. 6 a 15","4. 16+"))) -> 4. 16+ | Q6: =IF(OR(I6="Nenhum",I6="Planilha",I6="ContaAzul"),1,0) -> 0 | R6: =IF(AND(G6>=50,H6>=6,Q6=0),1,0) -> 1 | S6: =IF(AND(L6<>"Cliente Ativo",M6=0),1,0) -> 1 | T6: 3 | U6: Média | V6: =AVERAGEIF($D$2:$D$601,D6,$M$2:$M$601) -> 0.93975904 | W6: =AVERAGEIF($P$2:$P$601,P6,$M$2:$M$601) -> 0.97272727 | X6: =AVERAGEIF($O$2:$O$601,O6,$M$2:$M$601) -> 0.97938144 | Y6: =AVERAGEIF($I$2:$I$601,I6,$M$2:$M$601) -> 0.37662338 | Z6: =AVERAGEIF($N$2:$N$601,N6,$M$2:$M$601) -> 0.22302158 | AA6: =ROUND(AVERAGE(V6:Z6),10) -> 0.69830254 | AB6: =IF(AA6>=Como_Avaliar!$B$15,"Alta",IF(AA6>=Como_Avaliar!$B$16,"Média","Baixa")) -> Alta
A7: CTD00006 | B7: GO | C7: Centro-Oeste | D7: Autônomo | E7: Tecnologia | F7: 8 | G7: 22 | H7: 2 | I7: ContaAzul | J7: Não | K7: Não | L7: Prospect | M7: 0 | N7: =IF(F7<8,"1. < 8 anos",IF(F7<16,"2. 8 a 15 anos","3. 16+ anos")) -> 2. 8 a 15 anos | O7: =IF(G7<20,"1. < 20",IF(G7<50,"2. 20 a 49",IF(G7<150,"3. 50 a 149","4. 150+"))) -> 2. 20 a 49 | P7: =IF(H7<=2,"1. 1 a 2",IF(H7<=5,"2. 3 a 5",IF(H7<=15,"3. 6 a 15","4. 16+"))) -> 1. 1 a 2 | Q7: =IF(OR(I7="Nenhum",I7="Planilha",I7="ContaAzul"),1,0) -> 1 | R7: =IF(AND(G7>=50,H7>=6,Q7=0),1,0) -> 0 | S7: =IF(AND(L7<>"Cliente Ativo",M7=0),1,0) -> 1 | T7: 2 | U7: Baixa | V7: =AVERAGEIF($D$2:$D$601,D7,$M$2:$M$601) -> 0.068273092 | W7: =AVERAGEIF($P$2:$P$601,P7,$M$2:$M$601) -> 0.086792453 | X7: =AVERAGEIF($O$2:$O$601,O7,$M$2:$M$601) -> 0.25294118 | Y7: =AVERAGEIF($I$2:$I$601,I7,$M$2:$M$601) -> 0 | Z7: =AVERAGEIF($N$2:$N$601,N7,$M$2:$M$601) -> 0.22302158 | AA7: =ROUND(AVERAGE(V7:Z7),10) -> 0.12620566 | AB7: =IF(AA7>=Como_Avaliar!$B$15,"Alta",IF(AA7>=Como_Avaliar!$B$16,"Média","Baixa")) -> Baixa
A8: CTD00007 | B8: PE | C8: Nordeste | D8: Autônomo | E8: Construção Civil | F8: 29 | G8: 12 | H8: 1 | I8: Planilha | J8: Não | K8: Sim | L8: Lead Quente | M8: 1 | N8: =IF(F8<8,"1. < 8 anos",IF(F8<16,"2. 8 a 15 anos","3. 16+ anos")) -> 3. 16+ anos | O8: =IF(G8<20,"1. < 20",IF(G8<50,"2. 20 a 49",IF(G8<150,"3. 50 a 149","4. 150+"))) -> 1. < 20 | P8: =IF(H8<=2,"1. 1 a 2",IF(H8<=5,"2. 3 a 5",IF(H8<=15,"3. 6 a 15","4. 16+"))) -> 1. 1 a 2 | Q8: =IF(OR(I8="Nenhum",I8="Planilha",I8="ContaAzul"),1,0) -> 1 | R8: =IF(AND(G8>=50,H8>=6,Q8=0),1,0) -> 0 | S8: =IF(AND(L8<>"Cliente Ativo",M8=0),1,0) -> 0 | V8: =AVERAGEIF($D$2:$D$601,D8,$M$2:$M$601) -> 0.068273092 | W8: =AVERAGEIF($P$2:$P$601,P8,$M$2:$M$601) -> 0.086792453 | X8: =AVERAGEIF($O$2:$O$601,O8,$M$2:$M$601) -> 0.10309278 | Y8: =AVERAGEIF($I$2:$I$601,I8,$M$2:$M$601) -> 0.15625 | Z8: =AVERAGEIF($N$2:$N$601,N8,$M$2:$M$601) -> 0.56634304 | AA8: =ROUND(AVERAGE(V8:Z8),10) -> 0.19615027 | AB8: =IF(AA8>=Como_Avaliar!$B$15,"Alta",IF(AA8>=Como_Avaliar!$B$16,"Média","Baixa")) -> Baixa
A9: CTD00008 | B9: SP | C9: Sudeste | D9: Autônomo | E9: Serviços | F9: 21 | G9: 21 | H9: 2 | I9: Planilha | J9: Sim | K9: Sim | L9: Prospect | M9: 0 | N9: =IF(F9<8,"1. < 8 anos",IF(F9<16,"2. 8 a 15 anos","3. 16+ anos")) -> 3. 16+ anos | O9: =IF(G9<20,"1. < 20",IF(G9<50,"2. 20 a 49",IF(G9<150,"3. 50 a 149","4. 150+"))) -> 2. 20 a 49 | P9: =IF(H9<=2,"1. 1 a 2",IF(H9<=5,"2. 3 a 5",IF(H9<=15,"3. 6 a 15","4. 16+"))) -> 1. 1 a 2 | Q9: =IF(OR(I9="Nenhum",I9="Planilha",I9="ContaAzul"),1,0) -> 1 | R9: =IF(AND(G9>=50,H9>=6,Q9=0),1,0) -> 0 | S9: =IF(AND(L9<>"Cliente Ativo",M9=0),1,0) -> 1 | T9: 2 | U9: Baixa | V9: =AVERAGEIF($D$2:$D$601,D9,$M$2:$M$601) -> 0.068273092 | W9: =AVERAGEIF($P$2:$P$601,P9,$M$2:$M$601) -> 0.086792453 | X9: =AVERAGEIF($O$2:$O$601,O9,$M$2:$M$601) -> 0.25294118 | Y9: =AVERAGEIF($I$2:$I$601,I9,$M$2:$M$601) -> 0.15625 | Z9: =AVERAGEIF($N$2:$N$601,N9,$M$2:$M$601) -> 0.56634304 | AA9: =ROUND(AVERAGE(V9:Z9),10) -> 0.22611995 | AB9: =IF(AA9>=Como_Avaliar!$B$15,"Alta",IF(AA9>=Como_Avaliar!$B$16,"Média","Baixa")) -> Baixa
A10: CTD00009 | B10: MG | C10: Sudeste | D10: Autônomo | E10: Varejo/Comércio | F10: 7 | G10: 13 | H10: 1 | I10: Nenhum | J10: Não | K10: Não | L10: Lead Frio | M10: 0 | N10: =IF(F10<8,"1. < 8 anos",IF(F10<16,"2. 8 a 15 anos","3. 16+ anos")) -> 1. < 8 anos | O10: =IF(G10<20,"1. < 20",IF(G10<50,"2. 20 a 49",IF(G10<150,"3. 50 a 149","4. 150+"))) -> 1. < 20 | P10: =IF(H10<=2,"1. 1 a 2",IF(H10<=5,"2. 3 a 5",IF(H10<=15,"3. 6 a 15","4. 16+"))) -> 1. 1 a 2 | Q10: =IF(OR(I10="Nenhum",I10="Planilha",I10="ContaAzul"),1,0) -> 1 | R10: =IF(AND(G10>=50,H10>=6,Q10=0),1,0) -> 0 | S10: =IF(AND(L10<>"Cliente Ativo",M10=0),1,0) -> 1 | T10: 2 | U10: Baixa | V10: =AVERAGEIF($D$2:$D$601,D10,$M$2:$M$601) -> 0.068273092 | W10: =AVERAGEIF($P$2:$P$601,P10,$M$2:$M$601) -> 0.086792453 | X10: =AVERAGEIF($O$2:$O$601,O10,$M$2:$M$601) -> 0.10309278 | Y10: =AVERAGEIF($I$2:$I$601,I10,$M$2:$M$601) -> 0.065217391 | Z10: =AVERAGEIF($N$2:$N$601,N10,$M$2:$M$601) -> 0.22368421 | AA10: =ROUND(AVERAGE(V10:Z10),10) -> 0.10941199 | AB10: =IF(AA10>=Como_Avaliar!$B$15,"Alta",IF(AA10>=Como_Avaliar!$B$16,"Média","Baixa")) -> Baixa
A11: CTD00010 | B11: SP | C11: Sudeste | D11: Pequeno Escritório | E11: Serviços | F11: 26 | G11: 79 | H11: 3 | I11: Alterdata | J11: Não | K11: Não | L11: Prospect | M11: 1 | N11: =IF(F11<8,"1. < 8 anos",IF(F11<16,"2. 8 a 15 anos","3. 16+ anos")) -> 3. 16+ anos | O11: =IF(G11<20,"1. < 20",IF(G11<50,"2. 20 a 49",IF(G11<150,"3. 50 a 149","4. 150+"))) -> 3. 50 a 149 | P11: =IF(H11<=2,"1. 1 a 2",IF(H11<=5,"2. 3 a 5",IF(H11<=15,"3. 6 a 15","4. 16+"))) -> 2. 3 a 5 | Q11: =IF(OR(I11="Nenhum",I11="Planilha",I11="ContaAzul"),1,0) -> 0 | R11: =IF(AND(G11>=50,H11>=6,Q11=0),1,0) -> 0 | S11: =IF(AND(L11<>"Cliente Ativo",M11=0),1,0) -> 0 | V11: =AVERAGEIF($D$2:$D$601,D11,$M$2:$M$601) -> 0.43835616 | W11: =AVERAGEIF($P$2:$P$601,P11,$M$2:$M$601) -> 0.38095238 | X11: =AVERAGEIF($O$2:$O$601,O11,$M$2:$M$601) -> 0.58992806 | Y11: =AVERAGEIF($I$2:$I$601,I11,$M$2:$M$601) -> 0.65217391 | Z11: =AVERAGEIF($N$2:$N$601,N11,$M$2:$M$601) -> 0.56634304 | AA11: =ROUND(AVERAGE(V11:Z11),10) -> 0.52555071 | AB11: =IF(AA11>=Como_Avaliar!$B$15,"Alta",IF(AA11>=Como_Avaliar!$B$16,"Média","Baixa")) -> Alta
A12: CTD00011 | B12: SP | C12: Sudeste | D12: Autônomo | E12: Saúde | F12: 19 | G12: 19 | H12: 1 | I12: ContaAzul | J12: Sim | K12: Não | L12: Lead Quente | M12: 0 | N12: =IF(F12<8,"1. < 8 anos",IF(F12<16,"2. 8 a 15 anos","3. 16+ anos")) -> 3. 16+ anos | O12: =IF(G12<20,"1. < 20",IF(G12<50,"2. 20 a 49",IF(G12<150,"3. 50 a 149","4. 150+"))) -> 1. < 20 | P12: =IF(H12<=2,"1. 1 a 2",IF(H12<=5,"2. 3 a 5",IF(H12<=15,"3. 6 a 15","4. 16+"))) -> 1. 1 a 2 | Q12: =IF(OR(I12="Nenhum",I12="Planilha",I12="ContaAzul"),1,0) -> 1 | R12: =IF(AND(G12>=50,H12>=6,Q12=0),1,0) -> 0 | S12: =IF(AND(L12<>"Cliente Ativo",M12=0),1,0) -> 1 | T12: 2 | U12: Baixa | V12: =AVERAGEIF($D$2:$D$601,D12,$M$2:$M$601) -> 0.068273092 | W12: =AVERAGEIF($P$2:$P$601,P12,$M$2:$M$601) -> 0.086792453 | X12: =AVERAGEIF($O$2:$O$601,O12,$M$2:$M$601) -> 0.10309278 | Y12: =AVERAGEIF($I$2:$I$601,I12,$M$2:$M$601) -> 0 | Z12: =AVERAGEIF($N$2:$N$601,N12,$M$2:$M$601) -> 0.56634304 | AA12: =ROUND(AVERAGE(V12:Z12),10) -> 0.16490027 | AB12: =IF(AA12>=Como_Avaliar!$B$15,"Alta",IF(AA12>=Como_Avaliar!$B$16,"Média","Baixa")) -> Baixa
A13: CTD00012 | B13: PR | C13: Sul | D13: Pequeno Escritório | E13: Agronegócio | F13: 23 | G13: 77 | H13: 6 | I13: Planilha | J13: Sim | K13: Sim | L13: Prospect | M13: 1 | N13: =IF(F13<8,"1. < 8 anos",IF(F13<16,"2. 8 a 15 anos","3. 16+ anos")) -> 3. 16+ anos | O13: =IF(G13<20,"1. < 20",IF(G13<50,"2. 20 a 49",IF(G13<150,"3. 50 a 149","4. 150+"))) -> 3. 50 a 149 | P13: =IF(H13<=2,"1. 1 a 2",IF(H13<=5,"2. 3 a 5",IF(H13<=15,"3. 6 a 15","4. 16+"))) -> 3. 6 a 15 | Q13: =IF(OR(I13="Nenhum",I13="Planilha",I13="ContaAzul"),1,0) -> 1 | R13: =IF(AND(G13>=50,H13>=6,Q13=0),1,0) -> 0 | S13: =IF(AND(L13<>"Cliente Ativo",M13=0),1,0) -> 0 | V13: =AVERAGEIF($D$2:$D$601,D13,$M$2:$M$601) -> 0.43835616 | W13: =AVERAGEIF($P$2:$P$601,P13,$M$2:$M$601) -> 0.55319149 | X13: =AVERAGEIF($O$2:$O$601,O13,$M$2:$M$601) -> 0.58992806 | Y13: =AVERAGEIF($I$2:$I$601,I13,$M$2:$M$601) -> 0.15625 | Z13: =AVERAGEIF($N$2:$N$601,N13,$M$2:$M$601) -> 0.56634304 | AA13: =ROUND(AVERAGE(V13:Z13),10) -> 0.46081375 | AB13: =IF(AA13>=Como_Avaliar!$B$15,"Alta",IF(AA13>=Como_Avaliar!$B$16,"Média","Baixa")) -> Média
A14: CTD00013 | B14: SP | C14: Sudeste | D14: Médio Escritório | E14: Tecnologia | F14: 11 | G14: 241 | H14: 12 | I14: Totvs | J14: Não | K14: Não | L14: Lead Frio | M14: 1 | N14: =IF(F14<8,"1. < 8 anos",IF(F14<16,"2. 8 a 15 anos","3. 16+ anos")) -> 2. 8 a 15 anos | O14: =IF(G14<20,"1. < 20",IF(G14<50,"2. 20 a 49",IF(G14<150,"3. 50 a 149","4. 150+"))) -> 4. 150+ | P14: =IF(H14<=2,"1. 1 a 2",IF(H14<=5,"2. 3 a 5",IF(H14<=15,"3. 6 a 15","4. 16+"))) -> 3. 6 a 15 | Q14: =IF(OR(I14="Nenhum",I14="Planilha",I14="ContaAzul"),1,0) -> 0 | R14: =IF(AND(G14>=50,H14>=6,Q14=0),1,0) -> 1 | S14: =IF(AND(L14<>"Cliente Ativo",M14=0),1,0) -> 0 | V14: =AVERAGEIF($D$2:$D$601,D14,$M$2:$M$601) -> 0.93975904 | W14: =AVERAGEIF($P$2:$P$601,P14,$M$2:$M$601) -> 0.55319149 | X14: =AVERAGEIF($O$2:$O$601,O14,$M$2:$M$601) -> 0.97938144 | Y14: =AVERAGEIF($I$2:$I$601,I14,$M$2:$M$601) -> 0.58333333 | Z14: =AVERAGEIF($N$2:$N$601,N14,$M$2:$M$601) -> 0.22302158 | AA14: =ROUND(AVERAGE(V14:Z14),10) -> 0.65573738 | AB14: =IF(AA14>=Como_Avaliar!$B$15,"Alta",IF(AA14>=Como_Avaliar!$B$16,"Média","Baixa")) -> Alta
A15: CTD00014 | B15: SP | C15: Sudeste | D15: Autônomo | E15: Serviços | F15: 11 | G15: 21 | H15: 2 | I15: Domínio | J15: Sim | K15: Sim | L15: Lead Frio | M15: 0 | N15: =IF(F15<8,"1. < 8 anos",IF(F15<16,"2. 8 a 15 anos","3. 16+ anos")) -> 2. 8 a 15 anos | O15: =IF(G15<20,"1. < 20",IF(G15<50,"2. 20 a 49",IF(G15<150,"3. 50 a 149","4. 150+"))) -> 2. 20 a 49 | P15: =IF(H15<=2,"1. 1 a 2",IF(H15<=5,"2. 3 a 5",IF(H15<=15,"3. 6 a 15","4. 16+"))) -> 1. 1 a 2 | Q15: =IF(OR(I15="Nenhum",I15="Planilha",I15="ContaAzul"),1,0) -> 0 | R15: =IF(AND(G15>=50,H15>=6,Q15=0),1,0) -> 0 | S15: =IF(AND(L15<>"Cliente Ativo",M15=0),1,0) -> 1 | T15: 2 | U15: Baixa | V15: =AVERAGEIF($D$2:$D$601,D15,$M$2:$M$601) -> 0.068273092 | W15: =AVERAGEIF($P$2:$P$601,P15,$M$2:$M$601) -> 0.086792453 | X15: =AVERAGEIF($O$2:$O$601,O15,$M$2:$M$601) -> 0.25294118 | Y15: =AVERAGEIF($I$2:$I$601,I15,$M$2:$M$601) -> 0.37662338 | Z15: =AVERAGEIF($N$2:$N$601,N15,$M$2:$M$601) -> 0.22302158 | AA15: =ROUND(AVERAGE(V15:Z15),10) -> 0.20153034 | AB15: =IF(AA15>=Como_Avaliar!$B$15,"Alta",IF(AA15>=Como_Avaliar!$B$16,"Média","Baixa")) -> Baixa
A16: CTD00015 | B16: RS | C16: Sul | D16: Pequeno Escritório | E16: Indústria | F16: 24 | G16: 53 | H16: 4 | I16: Domínio | J16: Sim | K16: Não | L16: Prospect | M16: 1 | N16: =IF(F16<8,"1. < 8 anos",IF(F16<16,"2. 8 a 15 anos","3. 16+ anos")) -> 3. 16+ anos | O16: =IF(G16<20,"1. < 20",IF(G16<50,"2. 20 a 49",IF(G16<150,"3. 50 a 149","4. 150+"))) -> 3. 50 a 149 | P16: =IF(H16<=2,"1. 1 a 2",IF(H16<=5,"2. 3 a 5",IF(H16<=15,"3. 6 a 15","4. 16+"))) -> 2. 3 a 5 | Q16: =IF(OR(I16="Nenhum",I16="Planilha",I16="ContaAzul"),1,0) -> 0 | R16: =IF(AND(G16>=50,H16>=6,Q16=0),1,0) -> 0 | S16: =IF(AND(L16<>"Cliente Ativo",M16=0),1,0) -> 0 | V16: =AVERAGEIF($D$2:$D$601,D16,$M$2:$M$601) -> 0.43835616 | W16: =AVERAGEIF($P$2:$P$601,P16,$M$2:$M$601) -> 0.38095238 | X16: =AVERAGEIF($O$2:$O$601,O16,$M$2:$M$601) -> 0.58992806 | Y16: =AVERAGEIF($I$2:$I$601,I16,$M$2:$M$601) -> 0.37662338 | Z16: =AVERAGEIF($N$2:$N$601,N16,$M$2:$M$601) -> 0.56634304 | AA16: =ROUND(AVERAGE(V16:Z16),10) -> 0.4704406 | AB16: =IF(AA16>=Como_Avaliar!$B$15,"Alta",IF(AA16>=Como_Avaliar!$B$16,"Média","Baixa")) -> Média
A17: CTD00016 | B17: PR | C17: Sul | D17: Autônomo | E17: Saúde | F17: 21 | G17: 18 | H17: 2 | I17: Domínio | J17: Não | K17: Sim | L17: Lead Frio | M17: 1 | N17: =IF(F17<8,"1. < 8 anos",IF(F17<16,"2. 8 a 15 anos","3. 16+ anos")) -> 3. 16+ anos | O17: =IF(G17<20,"1. < 20",IF(G17<50,"2. 20 a 49",IF(G17<150,"3. 50 a 149","4. 150+"))) -> 1. < 20 | P17: =IF(H17<=2,"1. 1 a 2",IF(H17<=5,"2. 3 a 5",IF(H17<=15,"3. 6 a 15","4. 16+"))) -> 1. 1 a 2 | Q17: =IF(OR(I17="Nenhum",I17="Planilha",I17="ContaAzul"),1,0) -> 0 | R17: =IF(AND(G17>=50,H17>=6,Q17=0),1,0) -> 0 | S17: =IF(AND(L17<>"Cliente Ativo",M17=0),1,0) -> 0 | V17: =AVERAGEIF($D$2:$D$601,D17,$M$2:$M$601) -> 0.068273092 | W17: =AVERAGEIF($P$2:$P$601,P17,$M$2:$M$601) -> 0.086792453 | X17: =AVERAGEIF($O$2:$O$601,O17,$M$2:$M$601) -> 0.10309278 | Y17: =AVERAGEIF($I$2:$I$601,I17,$M$2:$M$601) -> 0.37662338 | Z17: =AVERAGEIF($N$2:$N$601,N17,$M$2:$M$601) -> 0.56634304 | AA17: =ROUND(AVERAGE(V17:Z17),10) -> 0.24022495 | AB17: =IF(AA17>=Como_Avaliar!$B$15,"Alta",IF(AA17>=Como_Avaliar!$B$16,"Média","Baixa")) -> Média
A18: CTD00017 | B18: RJ | C18: Sudeste | D18: Autônomo | E18: Tecnologia | F18: 4 | G18: 3 | H18: 2 | I18: Nenhum | J18: Não | K18: Sim | L18: Prospect | M18: 0 | N18: =IF(F18<8,"1. < 8 anos",IF(F18<16,"2. 8 a 15 anos","3. 16+ anos")) -> 1. < 8 anos | O18: =IF(G18<20,"1. < 20",IF(G18<50,"2. 20 a 49",IF(G18<150,"3. 50 a 149","4. 150+"))) -> 1. < 20 | P18: =IF(H18<=2,"1. 1 a 2",IF(H18<=5,"2. 3 a 5",IF(H18<=15,"3. 6 a 15","4. 16+"))) -> 1. 1 a 2 | Q18: =IF(OR(I18="Nenhum",I18="Planilha",I18="ContaAzul"),1,0) -> 1 | R18: =IF(AND(G18>=50,H18>=6,Q18=0),1,0) -> 0 | S18: =IF(AND(L18<>"Cliente Ativo",M18=0),1,0) -> 1 | T18: 2 | U18: Baixa | V18: =AVERAGEIF($D$2:$D$601,D18,$M$2:$M$601) -> 0.068273092 | W18: =AVERAGEIF($P$2:$P$601,P18,$M$2:$M$601) -> 0.086792453 | X18: =AVERAGEIF($O$2:$O$601,O18,$M$2:$M$601) -> 0.10309278 | Y18: =AVERAGEIF($I$2:$I$601,I18,$M$2:$M$601) -> 0.065217391 | Z18: =AVERAGEIF($N$2:$N$601,N18,$M$2:$M$601) -> 0.22368421 | AA18: =ROUND(AVERAGE(V18:Z18),10) -> 0.10941199 | AB18: =IF(AA18>=Como_Avaliar!$B$15,"Alta",IF(AA18>=Como_Avaliar!$B$16,"Média","Baixa")) -> Baixa
A19: CTD00018 | B19: SC | C19: Sul | D19: Autônomo | E19: Saúde | F19: 8 | G19: 14 | H19: 2 | I19: Questor | J19: Não | K19: Sim | L19: Prospect | M19: 0 | N19: =IF(F19<8,"1. < 8 anos",IF(F19<16,"2. 8 a 15 anos","3. 16+ anos")) -> 2. 8 a 15 anos | O19: =IF(G19<20,"1. < 20",IF(G19<50,"2. 20 a 49",IF(G19<150,"3. 50 a 149","4. 150+"))) -> 1. < 20 | P19: =IF(H19<=2,"1. 1 a 2",IF(H19<=5,"2. 3 a 5",IF(H19<=15,"3. 6 a 15","4. 16+"))) -> 1. 1 a 2 | Q19: =IF(OR(I19="Nenhum",I19="Planilha",I19="ContaAzul"),1,0) -> 0 | R19: =IF(AND(G19>=50,H19>=6,Q19=0),1,0) -> 0 | S19: =IF(AND(L19<>"Cliente Ativo",M19=0),1,0) -> 1 | T19: 3 | U19: Média | V19: =AVERAGEIF($D$2:$D$601,D19,$M$2:$M$601) -> 0.068273092 | W19: =AVERAGEIF($P$2:$P$601,P19,$M$2:$M$601) -> 0.086792453 | X19: =AVERAGEIF($O$2:$O$601,O19,$M$2:$M$601) -> 0.10309278 | Y19: =AVERAGEIF($I$2:$I$601,I19,$M$2:$M$601) -> 0.39751553 | Z19: =AVERAGEIF($N$2:$N$601,N19,$M$2:$M$601) -> 0.22302158 | AA19: =ROUND(AVERAGE(V19:Z19),10) -> 0.17573909 | AB19: =IF(AA19>=Como_Avaliar!$B$15,"Alta",IF(AA19>=Como_Avaliar!$B$16,"Média","Baixa")) -> Baixa
A20: CTD00019 | B20: DF | C20: Centro-Oeste | D20: Pequeno Escritório | E20: Varejo/Comércio | F20: 24 | G20: 57 | H20: 3 | I20: Totvs | J20: Não | K20: Não | L20: Prospect | M20: 1 | N20: =IF(F20<8,"1. < 8 anos",IF(F20<16,"2. 8 a 15 anos","3. 16+ anos")) -> 3. 16+ anos | O20: =IF(G20<20,"1. < 20",IF(G20<50,"2. 20 a 49",IF(G20<150,"3. 50 a 149","4. 150+"))) -> 3. 50 a 149 | P20: =IF(H20<=2,"1. 1 a 2",IF(H20<=5,"2. 3 a 5",IF(H20<=15,"3. 6 a 15","4. 16+"))) -> 2. 3 a 5 | Q20: =IF(OR(I20="Nenhum",I20="Planilha",I20="ContaAzul"),1,0) -> 0 | R20: =IF(AND(G20>=50,H20>=6,Q20=0),1,0) -> 0 | S20: =IF(AND(L20<>"Cliente Ativo",M20=0),1,0) -> 0 | V20: =AVERAGEIF($D$2:$D$601,D20,$M$2:$M$601) -> 0.43835616 | W20: =AVERAGEIF($P$2:$P$601,P20,$M$2:$M$601) -> 0.38095238 | X20: =AVERAGEIF($O$2:$O$601,O20,$M$2:$M$601) -> 0.58992806 | Y20: =AVERAGEIF($I$2:$I$601,I20,$M$2:$M$601) -> 0.58333333 | Z20: =AVERAGEIF($N$2:$N$601,N20,$M$2:$M$601) -> 0.56634304 | AA20: =ROUND(AVERAGE(V20:Z20),10) -> 0.5117826 | AB20: =IF(AA20>=Como_Avaliar!$B$15,"Alta",IF(AA20>=Como_Avaliar!$B$16,"Média","Baixa")) -> Alta
A21: CTD00020 | B21: SP | C21: Sudeste | D21: Pequeno Escritório | E21: Agronegócio | F21: 3 | G21: 29 | H21: 3 | I21: Domínio | J21: Não | K21: Não | L21: Lead Quente | M21: 0 | N21: =IF(F21<8,"1. < 8 anos",IF(F21<16,"2. 8 a 15 anos","3. 16+ anos")) -> 1. < 8 anos | O21: =IF(G21<20,"1. < 20",IF(G21<50,"2. 20 a 49",IF(G21<150,"3. 50 a 149","4. 150+"))) -> 2. 20 a 49 | P21: =IF(H21<=2,"1. 1 a 2",IF(H21<=5,"2. 3 a 5",IF(H21<=15,"3. 6 a 15","4. 16+"))) -> 2. 3 a 5 | Q21: =IF(OR(I21="Nenhum",I21="Planilha",I21="ContaAzul"),1,0) -> 0 | R21: =IF(AND(G21>=50,H21>=6,Q21=0),1,0) -> 0 | S21: =IF(AND(L21<>"Cliente Ativo",M21=0),1,0) -> 1 | T21: 3 | U21: Média | V21: =AVERAGEIF($D$2:$D$601,D21,$M$2:$M$601) -> 0.43835616 | W21: =AVERAGEIF($P$2:$P$601,P21,$M$2:$M$601) -> 0.38095238 | X21: =AVERAGEIF($O$2:$O$601,O21,$M$2:$M$601) -> 0.25294118 | Y21: =AVERAGEIF($I$2:$I$601,I21,$M$2:$M$601) -> 0.37662338 | Z21: =AVERAGEIF($N$2:$N$601,N21,$M$2:$M$601) -> 0.22368421 | AA21: =ROUND(AVERAGE(V21:Z21),10) -> 0.33451146 | AB21: =IF(AA21>=Como_Avaliar!$B$15,"Alta",IF(AA21>=Como_Avaliar!$B$16,"Média","Baixa")) -> Média
A22: CTD00021 | B22: DF | C22: Centro-Oeste | D22: Médio Escritório | E22: Varejo/Comércio | F22: 22 | G22: 166 | H22: 8 | I22: Domínio | J22: Não | K22: Não | L22: Prospect | M22: 1 | N22: =IF(F22<8,"1. < 8 anos",IF(F22<16,"2. 8 a 15 anos","3. 16+ anos")) -> 3. 16+ anos | O22: =IF(G22<20,"1. < 20",IF(G22<50,"2. 20 a 49",IF(G22<150,"3. 50 a 149","4. 150+"))) -> 4. 150+ | P22: =IF(H22<=2,"1. 1 a 2",IF(H22<=5,"2. 3 a 5",IF(H22<=15,"3. 6 a 15","4. 16+"))) -> 3. 6 a 15 | Q22: =IF(OR(I22="Nenhum",I22="Planilha",I22="ContaAzul"),1,0) -> 0 | R22: =IF(AND(G22>=50,H22>=6,Q22=0),1,0) -> 1 | S22: =IF(AND(L22<>"Cliente Ativo",M22=0),1,0) -> 0 | V22: =AVERAGEIF($D$2:$D$601,D22,$M$2:$M$601) -> 0.93975904 | W22: =AVERAGEIF($P$2:$P$601,P22,$M$2:$M$601) -> 0.55319149 | X22: =AVERAGEIF($O$2:$O$601,O22,$M$2:$M$601) -> 0.97938144 | Y22: =AVERAGEIF($I$2:$I$601,I22,$M$2:$M$601) -> 0.37662338 | Z22: =AVERAGEIF($N$2:$N$601,N22,$M$2:$M$601) -> 0.56634304 | AA22: =ROUND(AVERAGE(V22:Z22),10) -> 0.68305968 | AB22: =IF(AA22>=Como_Avaliar!$B$15,"Alta",IF(AA22>=Como_Avaliar!$B$16,"Média","Baixa")) -> Alta
A23: CTD00022 | B23: GO | C23: Centro-Oeste | D23: Pequeno Escritório | E23: Indústria | F23: 21 | G23: 54 | H23: 6 | I23: Totvs | J23: Sim | K23: Sim | L23: Prospect | M23: 0 | N23: =IF(F23<8,"1. < 8 anos",IF(F23<16,"2. 8 a 15 anos","3. 16+ anos")) -> 3. 16+ anos | O23: =IF(G23<20,"1. < 20",IF(G23<50,"2. 20 a 49",IF(G23<150,"3. 50 a 149","4. 150+"))) -> 3. 50 a 149 | P23: =IF(H23<=2,"1. 1 a 2",IF(H23<=5,"2. 3 a 5",IF(H23<=15,"3. 6 a 15","4. 16+"))) -> 3. 6 a 15 | Q23: =IF(OR(I23="Nenhum",I23="Planilha",I23="ContaAzul"),1,0) -> 0 | R23: =IF(AND(G23>=50,H23>=6,Q23=0),1,0) -> 1 | S23: =IF(AND(L23<>"Cliente Ativo",M23=0),1,0) -> 1 | T23: 3 | U23: Média | V23: =AVERAGEIF($D$2:$D$601,D23,$M$2:$M$601) -> 0.43835616 | W23: =AVERAGEIF($P$2:$P$601,P23,$M$2:$M$601) -> 0.55319149 | X23: =AVERAGEIF($O$2:$O$601,O23,$M$2:$M$601) -> 0.58992806 | Y23: =AVERAGEIF($I$2:$I$601,I23,$M$2:$M$601) -> 0.58333333 | Z23: =AVERAGEIF($N$2:$N$601,N23,$M$2:$M$601) -> 0.56634304 | AA23: =ROUND(AVERAGE(V23:Z23),10) -> 0.54623042 | AB23: =IF(AA23>=Como_Avaliar!$B$15,"Alta",IF(AA23>=Como_Avaliar!$B$16,"Média","Baixa")) -> Alta
A24: CTD00023 | B24: MG | C24: Sudeste | D24: Pequeno Escritório | E24: Varejo/Comércio | F24: 2 | G24: 18 | H24: 9 | I24: Totvs | J24: Não | K24: Sim | L24: Lead Frio | M24: 0 | N24: =IF(F24<8,"1. < 8 anos",IF(F24<16,"2. 8 a 15 anos","3. 16+ anos")) -> 1. < 8 anos | O24: =IF(G24<20,"1. < 20",IF(G24<50,"2. 20 a 49",IF(G24<150,"3. 50 a 149","4. 150+"))) -> 1. < 20 | P24: =IF(H24<=2,"1. 1 a 2",IF(H24<=5,"2. 3 a 5",IF(H24<=15,"3. 6 a 15","4. 16+"))) -> 3. 6 a 15 | Q24: =IF(OR(I24="Nenhum",I24="Planilha",I24="ContaAzul"),1,0) -> 0 | R24: =IF(AND(G24>=50,H24>=6,Q24=0),1,0) -> 0 | S24: =IF(AND(L24<>"Cliente Ativo",M24=0),1,0) -> 1 | T24: 2 | U24: Baixa | V24: =AVERAGEIF($D$2:$D$601,D24,$M$2:$M$601) -> 0.43835616 | W24: =AVERAGEIF($P$2:$P$601,P24,$M$2:$M$601) -> 0.55319149 | X24: =AVERAGEIF($O$2:$O$601,O24,$M$2:$M$601) -> 0.10309278 | Y24: =AVERAGEIF($I$2:$I$601,I24,$M$2:$M$601) -> 0.58333333 | Z24: =AVERAGEIF($N$2:$N$601,N24,$M$2:$M$601) -> 0.22368421 | AA24: =ROUND(AVERAGE(V24:Z24),10) -> 0.3803316 | AB24: =IF(AA24>=Como_Avaliar!$B$15,"Alta",IF(AA24>=Como_Avaliar!$B$16,"Média","Baixa")) -> Média
A25: CTD00024 | B25: SP | C25: Sudeste | D25: Pequeno Escritório | E25: Serviços | F25: 24 | G25: 75 | H25: 7 | I25: Questor | J25: Não | K25: Não | L25: Lead Frio | M25: 1 | N25: =IF(F25<8,"1. < 8 anos",IF(F25<16,"2. 8 a 15 anos","3. 16+ anos")) -> 3. 16+ anos | O25: =IF(G25<20,"1. < 20",IF(G25<50,"2. 20 a 49",IF(G25<150,"3. 50 a 149","4. 150+"))) -> 3. 50 a 149 | P25: =IF(H25<=2,"1. 1 a 2",IF(H25<=5,"2. 3 a 5",IF(H25<=15,"3. 6 a 15","4. 16+"))) -> 3. 6 a 15 | Q25: =IF(OR(I25="Nenhum",I25="Planilha",I25="ContaAzul"),1,0) -> 0 | R25: =IF(AND(G25>=50,H25>=6,Q25=0),1,0) -> 1 | S25: =IF(AND(L25<>"Cliente Ativo",M25=0),1,0) -> 0 | V25: =AVERAGEIF($D$2:$D$601,D25,$M$2:$M$601) -> 0.43835616 | W25: =AVERAGEIF($P$2:$P$601,P25,$M$2:$M$601) -> 0.55319149 | X25: =AVERAGEIF($O$2:$O$601,O25,$M$2:$M$601) -> 0.58992806 | Y25: =AVERAGEIF($I$2:$I$601,I25,$M$2:$M$601) -> 0.39751553 | Z25: =AVERAGEIF($N$2:$N$601,N25,$M$2:$M$601) -> 0.56634304 | AA25: =ROUND(AVERAGE(V25:Z25),10) -> 0.50906686 | AB25: =IF(AA25>=Como_Avaliar!$B$15,"Alta",IF(AA25>=Como_Avaliar!$B$16,"Média","Baixa")) -> Alta
A26: CTD00025 | B26: MA | C26: Nordeste | D26: Pequeno Escritório | E26: Saúde | F26: 12 | G26: 48 | H26: 6 | I26: Questor | J26: Não | K26: Não | L26: Cliente Ativo | M26: 0 | N26: =IF(F26<8,"1. < 8 anos",IF(F26<16,"2. 8 a 15 anos","3. 16+ anos")) -> 2. 8 a 15 anos | O26: =IF(G26<20,"1. < 20",IF(G26<50,"2. 20 a 49",IF(G26<150,"3. 50 a 149","4. 150+"))) -> 2. 20 a 49 | P26: =IF(H26<=2,"1. 1 a 2",IF(H26<=5,"2. 3 a 5",IF(H26<=15,"3. 6 a 15","4. 16+"))) -> 3. 6 a 15 | Q26: =IF(OR(I26="Nenhum",I26="Planilha",I26="ContaAzul"),1,0) -> 0 | R26: =IF(AND(G26>=50,H26>=6,Q26=0),1,0) -> 0 | S26: =IF(AND(L26<>"Cliente Ativo",M26=0),1,0) -> 0 | V26: =AVERAGEIF($D$2:$D$601,D26,$M$2:$M$601) -> 0.43835616 | W26: =AVERAGEIF($P$2:$P$601,P26,$M$2:$M$601) -> 0.55319149 | X26: =AVERAGEIF($O$2:$O$601,O26,$M$2:$M$601) -> 0.25294118 | Y26: =AVERAGEIF($I$2:$I$601,I26,$M$2:$M$601) -> 0.39751553 | Z26: =AVERAGEIF($N$2:$N$601,N26,$M$2:$M$601) -> 0.22302158 | AA26: =ROUND(AVERAGE(V26:Z26),10) -> 0.37300519 | AB26: =IF(AA26>=Como_Avaliar!$B$15,"Alta",IF(AA26>=Como_Avaliar!$B$16,"Média","Baixa")) -> Média
A27: CTD00026 | B27: RJ | C27: Sudeste | D27: Pequeno Escritório | E27: Saúde | F27: 6 | G27: 44 | H27: 3 | I27: Planilha | J27: Não | K27: Sim | L27: Prospect | M27: 0 | N27: =IF(F27<8,"1. < 8 anos",IF(F27<16,"2. 8 a 15 anos","3. 16+ anos")) -> 1. < 8 anos | O27: =IF(G27<20,"1. < 20",IF(G27<50,"2. 20 a 49",IF(G27<150,"3. 50 a 149","4. 150+"))) -> 2. 20 a 49 | P27: =IF(H27<=2,"1. 1 a 2",IF(H27<=5,"2. 3 a 5",IF(H27<=15,"3. 6 a 15","4. 16+"))) -> 2. 3 a 5 | Q27: =IF(OR(I27="Nenhum",I27="Planilha",I27="ContaAzul"),1,0) -> 1 | R27: =IF(AND(G27>=50,H27>=6,Q27=0),1,0) -> 0 | S27: =IF(AND(L27<>"Cliente Ativo",M27=0),1,0) -> 1 | T27: 4 | U27: Alta | V27: =AVERAGEIF($D$2:$D$601,D27,$M$2:$M$601) -> 0.43835616 | W27: =AVERAGEIF($P$2:$P$601,P27,$M$2:$M$601) -> 0.38095238 | X27: =AVERAGEIF($O$2:$O$601,O27,$M$2:$M$601) -> 0.25294118 | Y27: =AVERAGEIF($I$2:$I$601,I27,$M$2:$M$601) -> 0.15625 | Z27: =AVERAGEIF($N$2:$N$601,N27,$M$2:$M$601) -> 0.22368421 | AA27: =ROUND(AVERAGE(V27:Z27),10) -> 0.29043679 | AB27: =IF(AA27>=Como_Avaliar!$B$15,"Alta",IF(AA27>=Como_Avaliar!$B$16,"Média","Baixa")) -> Média
A28: CTD00027 | B28: SP | C28: Sudeste | D28: Pequeno Escritório | E28: Tecnologia | F28: 2 | G28: 21 | H28: 4 | I28: Alterdata | J28: Sim | K28: Sim | L28: Prospect | M28: 0 | N28: =IF(F28<8,"1. < 8 anos",IF(F28<16,"2. 8 a 15 anos","3. 16+ anos")) -> 1. < 8 anos | O28: =IF(G28<20,"1. < 20",IF(G28<50,"2. 20 a 49",IF(G28<150,"3. 50 a 149","4. 150+"))) -> 2. 20 a 49 | P28: =IF(H28<=2,"1. 1 a 2",IF(H28<=5,"2. 3 a 5",IF(H28<=15,"3. 6 a 15","4. 16+"))) -> 2. 3 a 5 | Q28: =IF(OR(I28="Nenhum",I28="Planilha",I28="ContaAzul"),1,0) -> 0 | R28: =IF(AND(G28>=50,H28>=6,Q28=0),1,0) -> 0 | S28: =IF(AND(L28<>"Cliente Ativo",M28=0),1,0) -> 1 | T28: 2 | U28: Baixa | V28: =AVERAGEIF($D$2:$D$601,D28,$M$2:$M$601) -> 0.43835616 | W28: =AVERAGEIF($P$2:$P$601,P28,$M$2:$M$601) -> 0.38095238 | X28: =AVERAGEIF($O$2:$O$601,O28,$M$2:$M$601) -> 0.25294118 | Y28: =AVERAGEIF($I$2:$I$601,I28,$M$2:$M$601) -> 0.65217391 | Z28: =AVERAGEIF($N$2:$N$601,N28,$M$2:$M$601) -> 0.22368421 | AA28: =ROUND(AVERAGE(V28:Z28),10) -> 0.38962157 | AB28: =IF(AA28>=Como_Avaliar!$B$15,"Alta",IF(AA28>=Como_Avaliar!$B$16,"Média","Baixa")) -> Média
