Workbook

Sheet LEIA-ME
A1: Desafio 3 — Priorização Comercial: Capacity & Foco dos ECs
A2: Tudo calculado por fórmulas a partir da base do case. Células verdes = resultados principais.
A4: Abas
A5: 1. Premissas — só parâmetros tirados da base: capacidade por EC, churn, corte de lead parado, território e ticket.
A6: 2. Gap_Meta (3a) — meta vs realizado por franquia e por EC equivalente, funil vs rede e tendência.
A7: 3. Regioes (3a) — onde se concentra o gap e o risco.
A8: 4. Simulador_Funil — quanto vale cada ponto percentual de conversão em cada etapa do funil.
A9: 5. Priorizacao (3b) — 303 contadores endereçáveis (regra do 1a: não é 'Cliente Ativo' e converteu_omie = 0) com tier de prioridade (Desafio 1c), intenção (pipeline), MRR esperado, onda e ordem de ataque.
A10: 6. Ondas_Capacidade (3b) — o framework: quem entra em cada onda, o que o EC faz e por quê.
A11: 7. EC_Adicional (3c) — onde alocar 1 EC adicional: demanda por EC × conversão do funil.
A12: 8. Execucao — base execucao_comercial (apoio).
A14: Escolhas e premissas
... A21: • Sem premissas externas: nenhum custo, ramp-up, SLA ou corte que não venha da base.

Sheet Premissas
A1: Parâmetros (todos tirados da base do case)
A3: Parâmetro | B3: Valor | C3: Fonte na base
A4: Leads trabalhados por EC/mês (capacidade) | B4: 16.5 | C4: Média de leads_trabalhados (execucao_comercial)
A5: Churn dos contratos | B5: 0.2055 | C5: Contratos Churned ÷ total (clientes_ativos)
A6: Lead parado a partir de (dias) | B6: 90 | C6: Nenhum lead Ganho da base fechou com mais de 89 dias (leads_pipeline)
A9: Território (estado → franquia)
A10: Estado | B10: Franquia | C10: Cobertura
A11: AM | B11: FRQ013 | C11: Própria
A12: BA | B12: FRQ010 | C12: Própria
A13: CE | B13: FRQ012 | C13: Própria
A14: DF | B14: FRQ008 | C14: Própria
A15: ES | B15: FRQ015 | C15: Própria
A16: GO | B16: FRQ009 | C16: Própria
A17: MA | B17: Sem franquia | C17: Sem franquia no estado (sem cobertura)
A18: MG | B18: FRQ004 | C18: Própria
A19: MS | B19: Sem franquia | C19: Sem franquia no estado (sem cobertura)
A20: MT | B20: Sem franquia | C20: Sem franquia no estado (sem cobertura)
A21: PA | B21: FRQ014 | C21: Própria
... A28: SP | B28: FRQ001 / FRQ002 | C28: Própria (cidade de São Paulo = SP Capital; demais = SP Interior)
A30: Ticket MRR por porte (média de mrr_inicial em clientes_ativos)
A31: Porte | B31: Ticket (R$)
A32: Pequeno Escritório | B32: 1121
A33: Grande Escritório | B33: 1097
A34: Médio Escritório | B34: 1052
A35: Autônomo | B35: 938

Sheet Gap_Meta
A1: 3a — Franquias vs meta de nMRR: onde está o gap e por quê
A2: Meta/realizado: aba franquias (oficial). Funil e tendência: execucao_comercial 2024 (proporções). Índice vs benchmark = taxa da franquia ÷ taxa da rede (1,00 = igual à rede).
A4: id | B4: Franquia | C4: UF | D4: Região | E4: Meses operando | F4: Nº ECs | G4: Meta nMRR/mês | H4: Realizado nMRR/mês | I4: Atingimento | J4: Gap (R$) | K4: Meta por EC | L4: Realizado por EC | M4: Realizado por EC ÷ média da rede | N4: Leads | O4: Reuniões | P4: Propostas | Q4: Fechamentos | R4: Lead→Reunião | S4: Reunião→Proposta | T4: Proposta→Fechamento | U4: Índice L→R | V4: Índice R→P | W4: Índice P→F | X4: Etapa mais fraca vs rede | Y4: Tendência H2 vs H1 | Z4: % EC-mês sem fechamento | AA4: Situação | AB4: Início (data_inicio)
A5: FRQ001 | B5: Franquia SP Capital | C5: SP | D5: Sudeste | E5: 18 | F5: 6 | G5: 45000 | H5: 52000 | I5: =H5/G5 -> 1.1555556 | J5: =MAX(0,G5-H5) -> 0 | K5: =G5/F5 -> 7500 | L5: =H5/F5 -> 8666.6667 | M5: =L5/L$20 -> 1.2753623 | N5: =SUMIFS(Execucao!$E$2:$E$529,Execucao!$B$2:$B$529,A5) -> 1142 | O5: =SUMIFS(Execucao!$F$2:$F$529,Execucao!$B$2:$B$529,A5) -> 488 | P5: =SUMIFS(Execucao!$G$2:$G$529,Execucao!$B$2:$B$529,A5) -> 243 | Q5: =SUMIFS(Execucao!$H$2:$H$529,Execucao!$B$2:$B$529,A5) -> 44 | R5: =O5/N5 -> 0.42732049 | S5: =P5/O5 -> 0.49795082 | T5: =Q5/P5 -> 0.18106996 | U5: =R5/R$21 -> 1.0277194 | V5: =S5/S$21 -> 1.002275 | W5: =T5/T$21 -> 0.94041247 | X5: =IF(U5=MIN(U5:W5),"Lead→Reunião",IF(V5=MIN(U5:W5),"Reunião→Proposta","Proposta→Fechamento")) -> Proposta→Fechamento | Y5: =SUMIFS(Execucao!$I$2:$I$529,Execucao!$B$2:$B$529,A5,Execucao!$J$2:$J$529,"H2")/SUMIFS(Execucao!$I$2:$I$529,Execucao!$B$2:$B$529,A5,Execucao!$J$2:$J$529,"H1")-1 -> 0.018257434 | Z5: =AVERAGEIFS(Execucao!$K$2:$K$529,Execucao!$B$2:$B$529,A5) -> 0.48611111 | AA5: =IF(I5>=1,"Na meta","Abaixo da meta") -> Na meta | AB5: 44772
A6: FRQ002 | B6: Franquia SP Interior | C6: SP | D6: Sudeste | E6: 12 | F6: 4 | G6: 28000 | H6: 31000 | I6: =H6/G6 -> 1.1071429 | J6: =MAX(0,G6-H6) -> 0 | K6: =G6/F6 -> 7000 | L6: =H6/F6 -> 7750 | M6: =L6/L$20 -> 1.1404682 | N6: =SUMIFS(Execucao!$E$2:$E$529,Execucao!$B$2:$B$529,A6) -> 789 | O6: =SUMIFS(Execucao!$F$2:$F$529,Execucao!$B$2:$B$529,A6) -> 312 | P6: =SUMIFS(Execucao!$G$2:$G$529,Execucao!$B$2:$B$529,A6) -> 149 | Q6: =SUMIFS(Execucao!$H$2:$H$529,Execucao!$B$2:$B$529,A6) -> 23 | R6: =O6/N6 -> 0.39543726 | S6: =P6/O6 -> 0.4775641 | T6: =Q6/P6 -> 0.15436242 | U6: =R6/R$21 -> 0.95103919 | V6: =S6/S$21 -> 0.9612406 | W6: =T6/T$21 -> 0.80170307 | X6: =IF(U6=MIN(U6:W6),"Lead→Reunião",IF(V6=MIN(U6:W6),"Reunião→Proposta","Proposta→Fechamento")) -> Proposta→Fechamento | Y6: =SUMIFS(Execucao!$I$2:$I$529,Execucao!$B$2:$B$529,A6,Execucao!$J$2:$J$529,"H2")/SUMIFS(Execucao!$I$2:$I$529,Execucao!$B$2:$B$529,A6,Execucao!$J$2:$J$529,"H1")-1 -> -0.2365488 | Z6: =AVERAGEIFS(Execucao!$K$2:$K$529,Execucao!$B$2:$B$529,A6) -> 0.625 | AA6: =IF(I6>=1,"Na meta","Abaixo da meta") -> Na meta | AB6: 44906
A7: FRQ003 | B7: Franquia RJ | C7: RJ | D7: Sudeste | E7: 14 | F7: 5 | G7: 32000 | H7: 28000 | I7: =H7/G7 -> 0.875 | J7: =MAX(0,G7-H7) -> 4000 | K7: =G7/F7 -> 6400 | L7: =H7/F7 -> 5600 | M7: =L7/L$20 -> 0.82408027 | N7: =SUMIFS(Execucao!$E$2:$E$529,Execucao!$B$2:$B$529,A7) -> 992 | O7: =SUMIFS(Execucao!$F$2:$F$529,Execucao!$B$2:$B$529,A7) -> 417 | P7: =SUMIFS(Execucao!$G$2:$G$529,Execucao!$B$2:$B$529,A7) -> 205 | Q7: =SUMIFS(Execucao!$H$2:$H$529,Execucao!$B$2:$B$529,A7) -> 40 | R7: =O7/N7 -> 0.4203629 | S7: =P7/O7 -> 0.49160671 | T7: =Q7/P7 -> 0.19512195 | U7: =R7/R$21 -> 1.0109861 | V7: =S7/S$21 -> 0.98950556 | W7: =T7/T$21 -> 1.0133935 | X7: =IF(U7=MIN(U7:W7),"Lead→Reunião",IF(V7=MIN(U7:W7),"Reunião→Proposta","Proposta→Fechamento")) -> Reunião→Proposta | Y7: =SUMIFS(Execucao!$I$2:$I$529,Execucao!$B$2:$B$529,A7,Execucao!$J$2:$J$529,"H2")/SUMIFS(Execucao!$I$2:$I$529,Execucao!$B$2:$B$529,A7,Execucao!$J$2:$J$529,"H1")-1 -> 0.5616508 | Z7: =AVERAGEIFS(Execucao!$K$2:$K$529,Execucao!$B$2:$B$529,A7) -> 0.45 | AA7: =IF(I7>=1,"Na meta","Abaixo da meta") -> Abaixo da meta | AB7: 45070
A8: FRQ004 | B8: Franquia MG | C8: MG | D8: Sudeste | E8: 10 | F8: 3 | G8: 22000 | H8: 25000 | I8: =H8/G8 -> 1.1363636 | J8: =MAX(0,G8-H8) -> 0 | K8: =G8/F8 -> 7333.3333 | L8: =H8/F8 -> 8333.3333 | M8: =L8/L$20 -> 1.2263099 | N8: =SUMIFS(Execucao!$E$2:$E$529,Execucao!$B$2:$B$529,A8) -> 593 | O8: =SUMIFS(Execucao!$F$2:$F$529,Execucao!$B$2:$B$529,A8) -> 245 | P8: =SUMIFS(Execucao!$G$2:$G$529,Execucao!$B$2:$B$529,A8) -> 127 | Q8: =SUMIFS(Execucao!$H$2:$H$529,Execucao!$B$2:$B$529,A8) -> 28 | R8: =O8/N8 -> 0.41315346 | S8: =P8/O8 -> 0.51836735 | T8: =Q8/P8 -> 0.22047244 | U8: =R8/R$21 -> 0.9936472 | V8: =S8/S$21 -> 1.0433693 | W8: =T8/T$21 -> 1.1450548 | X8: =IF(U8=MIN(U8:W8),"Lead→Reunião",IF(V8=MIN(U8:W8),"Reunião→Proposta","Proposta→Fechamento")) -> Lead→Reunião | Y8: =SUMIFS(Execucao!$I$2:$I$529,Execucao!$B$2:$B$529,A8,Execucao!$J$2:$J$529,"H2")/SUMIFS(Execucao!$I$2:$I$529,Execucao!$B$2:$B$529,A8,Execucao!$J$2:$J$529,"H1")-1 -> -0.33668796 | Z8: =AVERAGEIFS(Execucao!$K$2:$K$529,Execucao!$B$2:$B$529,A8) -> 0.41666667 | AA8: =IF(I8>=1,"Na meta","Abaixo da meta") -> Na meta | AB8: 45076
A9: FRQ005 | B9: Franquia PR | C9: PR | D9: Sul | E9: 16 | F9: 5 | G9: 30000 | H9: 34000 | I9: =H9/G9 -> 1.1333333 | J9: =MAX(0,G9-H9) -> 0 | K9: =G9/F9 -> 6000 | L9: =H9/F9 -> 6800 | M9: =L9/L$20 -> 1.0006689 | N9: =SUMIFS(Execucao!$E$2:$E$529,Execucao!$B$2:$B$529,A9) -> 981 | O9: =SUMIFS(Execucao!$F$2:$F$529,Execucao!$B$2:$B$529,A9) -> 397 | P9: =SUMIFS(Execucao!$G$2:$G$529,Execucao!$B$2:$B$529,A9) -> 196 | Q9: =SUMIFS(Execucao!$H$2:$H$529,Execucao!$B$2:$B$529,A9) -> 35 | R9: =O9/N9 -> 0.40468909 | S9: =P9/O9 -> 0.49370277 | T9: =Q9/P9 -> 0.17857143 | U9: =R9/R$21 -> 0.97329013 | V9: =S9/S$21 -> 0.9937245 | W9: =T9/T$21 -> 0.927436 | X9: =IF(U9=MIN(U9:W9),"Lead→Reunião",IF(V9=MIN(U9:W9),"Reunião→Proposta","Proposta→Fechamento")) -> Proposta→Fechamento | Y9: =SUMIFS(Execucao!$I$2:$I$529,Execucao!$B$2:$B$529,A9,Execucao!$J$2:$J$529,"H2")/SUMIFS(Execucao!$I$2:$I$529,Execucao!$B$2:$B$529,A9,Execucao!$J$2:$J$529,"H1")-1 -> -0.0026755945 | Z9: =AVERAGEIFS(Execucao!$K$2:$K$529,Execucao!$B$2:$B$529,A9) -> 0.56666667 | AA9: =IF(I9>=1,"Na meta","Abaixo da meta") -> Na meta | AB9: 45392
A10: FRQ006 | B10: Franquia SC | C10: SC | D10: Sul | E10: 8 | F10: 3 | G10: 18000 | H10: 21000 | I10: =H10/G10 -> 1.1666667 | J10: =MAX(0,G10-H10) -> 0 | K10: =G10/F10 -> 6000 | L10: =H10/F10 -> 7000 | M10: =L10/L$20 -> 1.0301003 | N10: =SUMIFS(Execucao!$E$2:$E$529,Execucao!$B$2:$B$529,A10) -> 576 | O10: =SUMIFS(Execucao!$F$2:$F$529,Execucao!$B$2:$B$529,A10) -> 247 | P10: =SUMIFS(Execucao!$G$2:$G$529,Execucao!$B$2:$B$529,A10) -> 119 | Q10: =SUMIFS(Execucao!$H$2:$H$529,Execucao!$B$2:$B$529,A10) -> 24 | R10: =O10/N10 -> 0.42881944 | S10: =P10/O10 -> 0.48178138 | T10: =Q10/P10 -> 0.20168067 | U10: =R10/R$21 -> 1.0313244 | V10: =S10/S$21 -> 0.96972913 | W10: =T10/T$21 -> 1.0474571 | X10: =IF(U10=MIN(U10:W10),"Lead→Reunião",IF(V10=MIN(U10:W10),"Reunião→Proposta","Proposta→Fechamento")) -> Reunião→Proposta | Y10: =SUMIFS(Execucao!$I$2:$I$529,Execucao!$B$2:$B$529,A10,Execucao!$J$2:$J$529,"H2")/SUMIFS(Execucao!$I$2:$I$529,Execucao!$B$2:$B$529,A10,Execucao!$J$2:$J$529,"H1")-1 -> -0.23386118 | Z10: =AVERAGEIFS(Execucao!$K$2:$K$529,Execucao!$B$2:$B$529,A10) -> 0.47222222 | AA10: =IF(I10>=1,"Na meta","Abaixo da meta") -> Na meta | AB10: 45345
A11: FRQ007 | B11: Franquia RS | C11: RS | D11: Sul | E11: 11 | F11: 4 | G11: 24000 | H11: 23000 | I11: =H11/G11 -> 0.95833333 | J11: =MAX(0,G11-H11) -> 1000 | K11: =G11/F11 -> 6000 | L11: =H11/F11 -> 5750 | M11: =L11/L$20 -> 0.84615385 | N11: =SUMIFS(Execucao!$E$2:$E$529,Execucao!$B$2:$B$529,A11) -> 850 | O11: =SUMIFS(Execucao!$F$2:$F$529,Execucao!$B$2:$B$529,A11) -> 344 | P11: =SUMIFS(Execucao!$G$2:$G$529,Execucao!$B$2:$B$529,A11) -> 168 | Q11: =SUMIFS(Execucao!$H$2:$H$529,Execucao!$B$2:$B$529,A11) -> 32 | R11: =O11/N11 -> 0.40470588 | S11: =P11/O11 -> 0.48837209 | T11: =Q11/P11 -> 0.19047619 | U11: =R11/R$21 -> 0.97333051 | V11: =S11/S$21 -> 0.98299491 | W11: =T11/T$21 -> 0.98926507 | X11: =IF(U11=MIN(U11:W11),"Lead→Reunião",IF(V11=MIN(U11:W11),"Reunião→Proposta","Proposta→Fechamento")) -> Lead→Reunião | Y11: =SUMIFS(Execucao!$I$2:$I$529,Execucao!$B$2:$B$529,A11,Execucao!$J$2:$J$529,"H2")/SUMIFS(Execucao!$I$2:$I$529,Execucao!$B$2:$B$529,A11,Execucao!$J$2:$J$529,"H1")-1 -> 0.25445338 | Z11: =AVERAGEIFS(Execucao!$K$2:$K$529,Execucao!$B$2:$B$529,A11) -> 0.52083333 | AA11: =IF(I11>=1,"Na meta","Abaixo da meta") -> Abaixo da meta | AB11: 45245
A12: FRQ008 | B12: Franquia DF | C12: DF | D12: Centro-Oeste | E12: 9 | F12: 3 | G12: 20000 | H12: 18000 | I12: =H12/G12 -> 0.9 | J12: =MAX(0,G12-H12) -> 2000 | K12: =G12/F12 -> 6666.6667 | L12: =H12/F12 -> 6000 | M12: =L12/L$20 -> 0.88294314 | N12: =SUMIFS(Execucao!$E$2:$E$529,Execucao!$B$2:$B$529,A12) -> 559 | O12: =SUMIFS(Execucao!$F$2:$F$529,Execucao!$B$2:$B$529,A12) -> 233 | P12: =SUMIFS(Execucao!$G$2:$G$529,Execucao!$B$2:$B$529,A12) -> 116 | Q12: =SUMIFS(Execucao!$H$2:$H$529,Execucao!$B$2:$B$529,A12) -> 23 | R12: =O12/N12 -> 0.41681574 | S12: =P12/O12 -> 0.49785408 | T12: =Q12/P12 -> 0.19827586 | U12: =R12/R$21 -> 1.0024551 | V12: =S12/S$21 -> 1.0020802 | W12: =T12/T$21 -> 1.0297738 | X12: =IF(U12=MIN(U12:W12),"Lead→Reunião",IF(V12=MIN(U12:W12),"Reunião→Proposta","Proposta→Fechamento")) -> Reunião→Proposta | Y12: =SUMIFS(Execucao!$I$2:$I$529,Execucao!$B$2:$B$529,A12,Execucao!$J$2:$J$529,"H2")/SUMIFS(Execucao!$I$2:$I$529,Execucao!$B$2:$B$529,A12,Execucao!$J$2:$J$529,"H1")-1 -> -0.38478871 | Z12: =AVERAGEIFS(Execucao!$K$2:$K$529,Execucao!$B$2:$B$529,A12) -> 0.5 | AA12: =IF(I12>=1,"Na meta","Abaixo da meta") -> Abaixo da meta | AB12: 44909
A13: FRQ009 | B13: Franquia GO | C13: GO | D13: Centro-Oeste | E13: 7 | F13: 2 | G13: 16000 | H13: 14000 | I13: =H13/G13 -> 0.875 | J13: =MAX(0,G13-H13) -> 2000 | K13: =G13/F13 -> 8000 | L13: =H13/F13 -> 7000 | M13: =L13/L$20 -> 1.0301003 | N13: =SUMIFS(Execucao!$E$2:$E$529,Execucao!$B$2:$B$529,A13) -> 410 | O13: =SUMIFS(Execucao!$F$2:$F$529,Execucao!$B$2:$B$529,A13) -> 170 | P13: =SUMIFS(Execucao!$G$2:$G$529,Execucao!$B$2:$B$529,A13) -> 81 | Q13: =SUMIFS(Execucao!$H$2:$H$529,Execucao!$B$2:$B$529,A13) -> 17 | R13: =O13/N13 -> 0.41463415 | S13: =P13/O13 -> 0.47647059 | T13: =Q13/P13 -> 0.20987654 | U13: =R13/R$21 -> 0.9972083 | V13: =S13/S$21 -> 0.95903958 | W13: =T13/T$21 -> 1.0900235 | X13: =IF(U13=MIN(U13:W13),"Lead→Reunião",IF(V13=MIN(U13:W13),"Reunião→Proposta","Proposta→Fechamento")) -> Reunião→Proposta | Y13: =SUMIFS(Execucao!$I$2:$I$529,Execucao!$B$2:$B$529,A13,Execucao!$J$2:$J$529,"H2")/SUMIFS(Execucao!$I$2:$I$529,Execucao!$B$2:$B$529,A13,Execucao!$J$2:$J$529,"H1")-1 -> 0.28343734 | Z13: =AVERAGEIFS(Execucao!$K$2:$K$529,Execucao!$B$2:$B$529,A13) -> 0.45833333 | AA13: =IF(I13>=1,"Na meta","Abaixo da meta") -> Abaixo da meta | AB13: 44732
A14: FRQ010 | B14: Franquia BA | C14: BA | D14: Nordeste | E14: 6 | F14: 2 | G14: 14000 | H14: 11000 | I14: =H14/G14 -> 0.78571429 | J14: =MAX(0,G14-H14) -> 3000 | K14: =G14/F14 -> 7000 | L14: =H14/F14 -> 5500 | M14: =L14/L$20 -> 0.80936455 | N14: =SUMIFS(Execucao!$E$2:$E$529,Execucao!$B$2:$B$529,A14) -> 448 | O14: =SUMIFS(Execucao!$F$2:$F$529,Execucao!$B$2:$B$529,A14) -> 192 | P14: =SUMIFS(Execucao!$G$2:$G$529,Execucao!$B$2:$B$529,A14) -> 101 | Q14: =SUMIFS(Execucao!$H$2:$H$529,Execucao!$B$2:$B$529,A14) -> 20 | R14: =O14/N14 -> 0.42857143 | S14: =P14/O14 -> 0.52604167 | T14: =Q14/P14 -> 0.1980198 | U14: =R14/R$21 -> 1.0307279 | V14: =S14/S$21 -> 1.0588162 | W14: =T14/T$21 -> 1.0284439 | X14: =IF(U14=MIN(U14:W14),"Lead→Reunião",IF(V14=MIN(U14:W14),"Reunião→Proposta","Proposta→Fechamento")) -> Proposta→Fechamento | Y14: =SUMIFS(Execucao!$I$2:$I$529,Execucao!$B$2:$B$529,A14,Execucao!$J$2:$J$529,"H2")/SUMIFS(Execucao!$I$2:$I$529,Execucao!$B$2:$B$529,A14,Execucao!$J$2:$J$529,"H1")-1 -> -0.085893359 | Z14: =AVERAGEIFS(Execucao!$K$2:$K$529,Execucao!$B$2:$B$529,A14) -> 0.45833333 | AA14: =IF(I14>=1,"Na meta","Abaixo da meta") -> Abaixo da meta | AB14: 45191
A15: FRQ011 | B15: Franquia PE | C15: PE | D15: Nordeste | E15: 5 | F15: 2 | G15: 12000 | H15: 10000 | I15: =H15/G15 -> 0.83333333 | J15: =MAX(0,G15-H15) -> 2000 | K15: =G15/F15 -> 6000 | L15: =H15/F15 -> 5000 | M15: =L15/L$20 -> 0.73578595 | N15: =SUMIFS(Execucao!$E$2:$E$529,Execucao!$B$2:$B$529,A15) -> 382 | O15: =SUMIFS(Execucao!$F$2:$F$529,Execucao!$B$2:$B$529,A15) -> 163 | P15: =SUMIFS(Execucao!$G$2:$G$529,Execucao!$B$2:$B$529,A15) -> 83 | Q15: =SUMIFS(Execucao!$H$2:$H$529,Execucao!$B$2:$B$529,A15) -> 17 | R15: =O15/N15 -> 0.42670157 | S15: =P15/O15 -> 0.50920245 | T15: =Q15/P15 -> 0.20481928 | U15: =R15/R$21 -> 1.0262308 | V15: =S15/S$21 -> 1.0249222 | W15: =T15/T$21 -> 1.0637579 | X15: =IF(U15=MIN(U15:W15),"Lead→Reunião",IF(V15=MIN(U15:W15),"Reunião→Proposta","Proposta→Fechamento")) -> Reunião→Proposta | Y15: =SUMIFS(Execucao!$I$2:$I$529,Execucao!$B$2:$B$529,A15,Execucao!$J$2:$J$529,"H2")/SUMIFS(Execucao!$I$2:$I$529,Execucao!$B$2:$B$529,A15,Execucao!$J$2:$J$529,"H1")-1 -> 0.068414743 | Z15: =AVERAGEIFS(Execucao!$K$2:$K$529,Execucao!$B$2:$B$529,A15) -> 0.45833333 | AA15: =IF(I15>=1,"Na meta","Abaixo da meta") -> Abaixo da meta | AB15: 44868
A16: FRQ012 | B16: Franquia CE | C16: CE | D16: Nordeste | E16: 4 | F16: 1 | G16: 10000 | H16: 8500 | I16: =H16/G16 -> 0.85 | J16: =MAX(0,G16-H16) -> 1500 | K16: =G16/F16 -> 10000 | L16: =H16/F16 -> 8500 | M16: =L16/L$20 -> 1.2508361 | N16: =SUMIFS(Execucao!$E$2:$E$529,Execucao!$B$2:$B$529,A16) -> 194 | O16: =SUMIFS(Execucao!$F$2:$F$529,Execucao!$B$2:$B$529,A16) -> 78 | P16: =SUMIFS(Execucao!$G$2:$G$529,Execucao!$B$2:$B$529,A16) -> 37 | Q16: =SUMIFS(Execucao!$H$2:$H$529,Execucao!$B$2:$B$529,A16) -> 8 | R16: =O16/N16 -> 0.40206186 | S16: =P16/O16 -> 0.47435897 | T16: =Q16/P16 -> 0.21621622 | U16: =R16/R$21 -> 0.96697155 | V16: =S16/S$21 -> 0.95478932 | W16: =T16/T$21 -> 1.1229495 | X16: =IF(U16=MIN(U16:W16),"Lead→Reunião",IF(V16=MIN(U16:W16),"Reunião→Proposta","Proposta→Fechamento")) -> Reunião→Proposta | Y16: =SUMIFS(Execucao!$I$2:$I$529,Execucao!$B$2:$B$529,A16,Execucao!$J$2:$J$529,"H2")/SUMIFS(Execucao!$I$2:$I$529,Execucao!$B$2:$B$529,A16,Execucao!$J$2:$J$529,"H1")-1 -> -0.054860281 | Z16: =AVERAGEIFS(Execucao!$K$2:$K$529,Execucao!$B$2:$B$529,A16) -> 0.5 | AA16: =IF(I16>=1,"Na meta","Abaixo da meta") -> Abaixo da meta | AB16: 44934
... A19: FRQ015 | B19: Franquia ES | C19: ES | D19: Sudeste | E19: 5 | F19: 2 | G19: 11000 | H19: 12000 | I19: =H19/G19 -> 1.0909091 | J19: =MAX(0,G19-H19) -> 0 | K19: =G19/F19 -> 5500 | L19: =H19/F19 -> 6000 | M19: =L19/L$20 -> 0.88294314 | N19: =SUMIFS(Execucao!$E$2:$E$529,Execucao!$B$2:$B$529,A19) -> 396 | O19: =SUMIFS(Execucao!$F$2:$F$529,Execucao!$B$2:$B$529,A19) -> 176 | P19: =SUMIFS(Execucao!$G$2:$G$529,Execucao!$B$2:$B$529,A19) -> 93 | Q19: =SUMIFS(Execucao!$H$2:$H$529,Execucao!$B$2:$B$529,A19) -> 22 | R19: =O19/N19 -> 0.44444444 | S19: =P19/O19 -> 0.52840909 | T19: =Q19/P19 -> 0.23655914 | U19: =R19/R$21 -> 1.068903 | V19: =S19/S$21 -> 1.0635813 | W19: =T19/T$21 -> 1.2286034 | X19: =IF(U19=MIN(U19:W19),"Lead→Reunião",IF(V19=MIN(U19:W19),"Reunião→Proposta","Proposta→Fechamento")) -> Reunião→Proposta | Y19: =SUMIFS(Execucao!$I$2:$I$529,Execucao!$B$2:$B$529,A19,Execucao!$J$2:$J$529,"H2")/SUMIFS(Execucao!$I$2:$I$529,Execucao!$B$2:$B$529,A19,Execucao!$J$2:$J$529,"H1")-1 -> 0.45496244 | Z19: =AVERAGEIFS(Execucao!$K$2:$K$529,Execucao!$B$2:$B$529,A19) -> 0.33333333 | AA19: =IF(I19>=1,"Na meta","Abaixo da meta") -> Na meta | AB19: 45070
B20: Total da rede | F20: =SUM(F5:F19) -> 44 | G20: =SUM(G5:G19) -> 297500 | H20: =SUM(H5:H19) -> 299000 | I20: =H20/G20 -> 1.005042 | J20: =SUM(J5:J19) -> 19500 | K20: =G20/F20 -> 6761.3636 | L20: =H20/F20 -> 6795.4545 | N20: =SUM(N5:N19) -> 8699 | O20: =SUM(O5:O19) -> 3617 | P20: =SUM(P5:P19) -> 1797 | Q20: =SUM(Q5:Q19) -> 346
B21: Benchmark da rede (funil) | R21: =O20/N20 -> 0.41579492 | S21: =P20/O20 -> 0.49682057 | T21: =Q20/P20 -> 0.19254313 | Z21: =AVERAGE(Execucao!$K$2:$K$529) -> 0.49431818
A23: Leitura
A24: Gap total das franquias abaixo da meta (R$/mês) | D24: =J20 -> 19500
A25: Franquias abaixo da meta | D25: =COUNTIF(I5:I19,"<1") -> 9
A26: Correlação meses_operando × atingimento | D26: =CORREL(E5:E19,I5:I19) -> 0.64820513
A27: Correlação nº de ECs × atingimento | D27: =CORREL(F5:F19,I5:I19) -> 0.642042
A28: Faixa dos índices L→R e R→P entre franquias | D28: =FIXED(MIN(U5:V19),2)&" a "&FIXED(MAX(U5:V19),2) -> 0,94 a 1,10
A29: Faixa do índice P→F entre franquias | D29: =FIXED(MIN(W5:W19),2)&" a "&FIXED(MAX(W5:W19),2) -> 0,80 a 1,23
A30: Correlação índice P→F × atingimento | D30: =CORREL(W5:W19,I5:I19) -> 0.15015811
A31: Correlação antiguidade pela data_inicio × atingimento (início mais cedo = mais antiga) | D31: =-CORREL(AB5:AB19,I5:I19) -> -0.36600873
A32: Correlação meses_operando × nº de ECs | D32: =CORREL(E5:E19,F5:F19) -> 0.98572943
A34: 1. O funil não explica o gap: L→R e R→P são quase iguais entre franquias; P→F varia mais, mas quase não se relaciona com o atingimento (correlação ~0,15, contra ~0,64 do nº de ECs). Leads trabalhados por EC variam pouco (15 a 19 por mês).
A35: 2. O gap está nas franquias pequenas: das 7 franquias com 1 a 2 ECs, 6 estão abaixo da meta (só o ES bate). O CE tem a maior meta por EC da rede (R$ 10 mil) e realiza acima da média por EC: parte do gap é meta, não execução.
A36: 3. Governança: meses_operando conta a mesma história (correlação ~0,99 com o nº de ECs), mas contradiz a data_inicio (coluna AB): pela data de início, as franquias mais antigas atingem MENOS (correlação ~-0,37). Por isso a leitura usa o nº de ECs, que não tem contradição na base.
A37: 4. RJ: 5 ECs, maior gap absoluto (R$ 4 mil) e realizado por EC de R$ 5,6 mil, abaixo da média da rede.
A38: 5. Maiores quedas de nMRR na execução do 2º semestre: DF, MG, SP Interior e SC (coluna Y) — inclusive em franquias na meta.
A39: Nível de EC: id_executivo não identifica o EC; usamos o EC equivalente (franquia ÷ nº de ECs) e a dispersão (% de EC-mês sem fechamento). Recomendação: ID único de EC no CRM.

Sheet Regioes
A1: 3a — Concentração do gap e do risco por região
A3: Região | B3: Franquias | C3: Abaixo da meta | D3: % abaixo | E3: ECs | F3: Meta nMRR/mês | G3: Realizado nMRR/mês | H3: Atingimento da região | I3: Gap das franquias abaixo da meta (R$) | J3: % do gap total | K3: Meses operando (média)
A4: Sudeste | B4: =COUNTIF(Gap_Meta!$D$5:$D$19,A4) -> 5 | C4: =COUNTIFS(Gap_Meta!$D$5:$D$19,A4,Gap_Meta!$I$5:$I$19,"<1") -> 1 | D4: =C4/B4 -> 0.2 | E4: =SUMIF(Gap_Meta!$D$5:$D$19,A4,Gap_Meta!$F$5:$F$19) -> 20 | F4: =SUMIF(Gap_Meta!$D$5:$D$19,A4,Gap_Meta!$G$5:$G$19) -> 138000 | G4: =SUMIF(Gap_Meta!$D$5:$D$19,A4,Gap_Meta!$H$5:$H$19) -> 148000 | H4: =G4/F4 -> 1.0724638 | I4: =SUMIF(Gap_Meta!$D$5:$D$19,A4,Gap_Meta!$J$5:$J$19) -> 4000 | J4: =I4/SUM($I$4:$I$8) -> 0.20512821 | K4: =AVERAGEIF(Gap_Meta!$D$5:$D$19,A4,Gap_Meta!$E$5:$E$19) -> 11.8
A5: Sul | B5: =COUNTIF(Gap_Meta!$D$5:$D$19,A5) -> 3 | C5: =COUNTIFS(Gap_Meta!$D$5:$D$19,A5,Gap_Meta!$I$5:$I$19,"<1") -> 1 | D5: =C5/B5 -> 0.33333333 | E5: =SUMIF(Gap_Meta!$D$5:$D$19,A5,Gap_Meta!$F$5:$F$19) -> 12 | F5: =SUMIF(Gap_Meta!$D$5:$D$19,A5,Gap_Meta!$G$5:$G$19) -> 72000 | G5: =SUMIF(Gap_Meta!$D$5:$D$19,A5,Gap_Meta!$H$5:$H$19) -> 78000 | H5: =G5/F5 -> 1.0833333 | I5: =SUMIF(Gap_Meta!$D$5:$D$19,A5,Gap_Meta!$J$5:$J$19) -> 1000 | J5: =I5/SUM($I$4:$I$8) -> 0.051282051 | K5: =AVERAGEIF(Gap_Meta!$D$5:$D$19,A5,Gap_Meta!$E$5:$E$19) -> 11.666667
A6: Centro-Oeste | B6: =COUNTIF(Gap_Meta!$D$5:$D$19,A6) -> 2 | C6: =COUNTIFS(Gap_Meta!$D$5:$D$19,A6,Gap_Meta!$I$5:$I$19,"<1") -> 2 | D6: =C6/B6 -> 1 | E6: =SUMIF(Gap_Meta!$D$5:$D$19,A6,Gap_Meta!$F$5:$F$19) -> 5 | F6: =SUMIF(Gap_Meta!$D$5:$D$19,A6,Gap_Meta!$G$5:$G$19) -> 36000 | G6: =SUMIF(Gap_Meta!$D$5:$D$19,A6,Gap_Meta!$H$5:$H$19) -> 32000 | H6: =G6/F6 -> 0.88888889 | I6: =SUMIF(Gap_Meta!$D$5:$D$19,A6,Gap_Meta!$J$5:$J$19) -> 4000 | J6: =I6/SUM($I$4:$I$8) -> 0.20512821 | K6: =AVERAGEIF(Gap_Meta!$D$5:$D$19,A6,Gap_Meta!$E$5:$E$19) -> 8
A7: Nordeste | B7: =COUNTIF(Gap_Meta!$D$5:$D$19,A7) -> 3 | C7: =COUNTIFS(Gap_Meta!$D$5:$D$19,A7,Gap_Meta!$I$5:$I$19,"<1") -> 3 | D7: =C7/B7 -> 1 | E7: =SUMIF(Gap_Meta!$D$5:$D$19,A7,Gap_Meta!$F$5:$F$19) -> 5 | F7: =SUMIF(Gap_Meta!$D$5:$D$19,A7,Gap_Meta!$G$5:$G$19) -> 36000 | G7: =SUMIF(Gap_Meta!$D$5:$D$19,A7,Gap_Meta!$H$5:$H$19) -> 29500 | H7: =G7/F7 -> 0.81944444 | I7: =SUMIF(Gap_Meta!$D$5:$D$19,A7,Gap_Meta!$J$5:$J$19) -> 6500 | J7: =I7/SUM($I$4:$I$8) -> 0.33333333 | K7: =AVERAGEIF(Gap_Meta!$D$5:$D$19,A7,Gap_Meta!$E$5:$E$19) -> 5
A8: Norte | B8: =COUNTIF(Gap_Meta!$D$5:$D$19,A8) -> 2 | C8: =COUNTIFS(Gap_Meta!$D$5:$D$19,A8,Gap_Meta!$I$5:$I$19,"<1") -> 2 | D8: =C8/B8 -> 1 | E8: =SUMIF(Gap_Meta!$D$5:$D$19,A8,Gap_Meta!$F$5:$F$19) -> 2 | F8: =SUMIF(Gap_Meta!$D$5:$D$19,A8,Gap_Meta!$G$5:$G$19) -> 15500 | G8: =SUMIF(Gap_Meta!$D$5:$D$19,A8,Gap_Meta!$H$5:$H$19) -> 11500 | H8: =G8/F8 -> 0.74193548 | I8: =SUMIF(Gap_Meta!$D$5:$D$19,A8,Gap_Meta!$J$5:$J$19) -> 4000 | J8: =I8/SUM($I$4:$I$8) -> 0.20512821 | K8: =AVERAGEIF(Gap_Meta!$D$5:$D$19,A8,Gap_Meta!$E$5:$E$19) -> 3
A9: Total | B9: =SUM(B4:B8) -> 15 | C9: =SUM(C4:C8) -> 9 | E9: =SUM(E4:E8) -> 44 | F9: =SUM(F4:F8) -> 297500 | G9: =SUM(G4:G8) -> 299000 | H9: =G9/F9 -> 1.005042 | I9: =SUM(I4:I8) -> 19500
A11: Leitura
A12: • Norte, Nordeste e Centro-Oeste: 100% das franquias abaixo da meta e a região inteira abaixo da meta (atingimento de 74%, 82% e 89%). São as regiões das menores franquias: 1 a 3 ECs (Norte e Nordeste, 1 a 2).
A13: • Sudeste e Sul batem a meta como região (107% e 108%): o gap é pontual, só do RJ (maior gap da rede) e do RS.
A14: • A rede como um todo bate a meta (R$ 299 mil realizados contra R$ 297,5 mil): os R$ 19,5 mil são o gap das 9 franquias abaixo da meta.

Sheet Simulador_Funil
A1: Quanto vale +1 p.p. em cada etapa do funil?
A2: Fechamentos por lead = (L→R) × (R→P) × (P→F). Um ganho de conversão aumenta o nMRR na mesma proporção (mesmo volume de leads e ticket). Resultado em % é independente da escala de receita.
A4: Etapa | B4: Taxa atual (rede) | C4: Ganho (p.p.) | D4: Taxa simulada
A5: Lead → Reunião | B5: =Gap_Meta!R21 -> 0.41579492 | C5: 0 | D5: =B5+C5 -> 0.41579492
A6: Reunião → Proposta | B6: =Gap_Meta!S21 -> 0.49682057 | C6: 0 | D6: =B6+C6 -> 0.49682057
A7: Proposta → Fechamento | B7: =Gap_Meta!T21 -> 0.19254313 | C7: 0.05 | D7: =B7+C7 -> 0.24254313
A9: Fechamentos por lead — atual | B9: =B5*B6*B7 -> 0.039774687
A10: Fechamentos por lead — simulado | B10: =D5*D6*D7 -> 0.05010346
A11: Uplift no nMRR | B11: =B10/B9-1 -> 0.25968208
A12: nMRR adicional/mês — rede (escala oficial) | B12: =B11*Gap_Meta!H20 -> 77644.942
A13: nMRR adicional/mês — 9 franquias abaixo da meta (escala oficial) | B13: =B11*SUMIFS(Gap_Meta!$H$5:$H$19,Gap_Meta!$I$5:$I$19,"<1") -> 32200.578
A14: Cobertura do gap de meta | B14: =B13/Gap_Meta!J20 -> 1.6513117
A16: Leitura: a etapa Proposta → Fechamento é a de menor taxa (~19%) — cada p.p. ali vale mais que nas outras etapas. Alavancas: qualificação antes da proposta, proposta padronizada e follow-up.

Sheet Priorizacao
A1: id_contador | B1: UF | C1: Cidade | D1: Região | E1: Porte | F1: Nº clientes | G1: ERP | H1: Status pelos contratos (clientes_ativos) | I1: Estágio do lead ativo | J1: Ordem do estágio | K1: Lead parado (>90d) | L1: ICP | M1: Score Fit + Engajamento (1c, 1 a 5) | N1: Tier (1c) | O1: Franquia responsável | P1: Cobertura | Q1: Ticket esperado (R$) | R1: MRR esperado (R$) | S1: Onda | T1: Ação da onda | U1: Ordem na franquia | V1: Fit da carteira (1c) | W1: Engajamento (1c) | X1: Propensão (Desafio 2)
A2: CTD00004 | B2: RJ | C2: Campos dos Goytacazes | D2: Sudeste | E2: Pequeno Escritório | F2: 35 | G2: Questor | H2: Prospect em pipeline | I2: Em Contato | J2: 2 | K2: 0 | L2: 0 | M2: 4 | N2: Alta | O2: =IF(B2="SP",IF(C2="São Paulo","FRQ001","FRQ002"),VLOOKUP(B2,Premissas!$A$11:$B$28,2,FALSE)) -> FRQ003 | P2: =IF(O2="Sem franquia","Sem franquia","Própria") -> Própria | Q2: =VLOOKUP(E2,Premissas!$A$32:$B$35,2,FALSE) -> 1121 | R2: =Q2*(1-Premissas!$B$5) -> 890.6345 | S2: =IF(J2>=3,1,IF(N2="Alta",2,IF(K2=1,3,IF(N2="Média",4,5)))) -> 2 | T2: =CHOOSE(S2,"1. Fechar (lead ativo em Reunião/Proposta)","2. Prospectar tier Alta","3. Requalificar ou encerrar lead parado","4. Nutrir (marketing/inbound)","5. Régua automatizada") -> 2. Prospectar tier Alta | U2: =COUNTIFS($O$2:$O$304,O2,$S$2:$S$304,"<"&S2)+COUNTIFS($O$2:$O$304,O2,$S$2:$S$304,S2,$R$2:$R$304,">"&R2)+1 -> 5 | V2: Alto | W2: Morno | X2: 0.3386
A3: CTD00005 | B3: MT | C3: Cuiabá | D3: Centro-Oeste | E3: Médio Escritório | F3: 160 | G3: Domínio | H3: Prospect em pipeline | I3: Sem lead ativo | J3: 0 | K3: 1 | L3: 1 | M3: 3 | N3: Média | O3: =IF(B3="SP",IF(C3="São Paulo","FRQ001","FRQ002"),VLOOKUP(B3,Premissas!$A$11:$B$28,2,FALSE)) -> Sem franquia | P3: =IF(O3="Sem franquia","Sem franquia","Própria") -> Sem franquia | Q3: =VLOOKUP(E3,Premissas!$A$32:$B$35,2,FALSE) -> 1052 | R3: =Q3*(1-Premissas!$B$5) -> 835.814 | S3: =IF(J3>=3,1,IF(N3="Alta",2,IF(K3=1,3,IF(N3="Média",4,5)))) -> 3 | T3: =CHOOSE(S3,"1. Fechar (lead ativo em Reunião/Proposta)","2. Prospectar tier Alta","3. Requalificar ou encerrar lead parado","4. Nutrir (marketing/inbound)","5. Régua automatizada") -> 3. Requalificar ou encerrar lead parado | U3: =COUNTIFS($O$2:$O$304,O3,$S$2:$S$304,"<"&S3)+COUNTIFS($O$2:$O$304,O3,$S$2:$S$304,S3,$R$2:$R$304,">"&R3)+1 -> 8 | V3: Alto | W3: Frio | X3: 0.6983
A4: CTD00006 | B4: GO | C4: Aparecida de Goiânia | D4: Centro-Oeste | E4: Autônomo | F4: 22 | G4: ContaAzul | H4: Prospect sem contato | I4: Sem lead ativo | J4: 0 | K4: 0 | L4: 0 | M4: 2 | N4: Baixa | O4: =IF(B4="SP",IF(C4="São Paulo","FRQ001","FRQ002"),VLOOKUP(B4,Premissas!$A$11:$B$28,2,FALSE)) -> FRQ009 | P4: =IF(O4="Sem franquia","Sem franquia","Própria") -> Própria | Q4: =VLOOKUP(E4,Premissas!$A$32:$B$35,2,FALSE) -> 938 | R4: =Q4*(1-Premissas!$B$5) -> 745.241 | S4: =IF(J4>=3,1,IF(N4="Alta",2,IF(K4=1,3,IF(N4="Média",4,5)))) -> 5 | T4: =CHOOSE(S4,"1. Fechar (lead ativo em Reunião/Proposta)","2. Prospectar tier Alta","3. Requalificar ou encerrar lead parado","4. Nutrir (marketing/inbound)","5. Régua automatizada") -> 5. Régua automatizada | U4: =COUNTIFS($O$2:$O$304,O4,$S$2:$S$304,"<"&S4)+COUNTIFS($O$2:$O$304,O4,$S$2:$S$304,S4,$R$2:$R$304,">"&R4)+1 -> 6 | V4: Médio | W4: Frio | X4: 0.1262
A5: CTD00008 | B5: SP | C5: Osasco | D5: Sudeste | E5: Autônomo | F5: 21 | G5: Planilha | H5: Prospect sem contato | I5: Sem lead ativo | J5: 0 | K5: 0 | L5: 0 | M5: 2 | N5: Baixa | O5: =IF(B5="SP",IF(C5="São Paulo","FRQ001","FRQ002"),VLOOKUP(B5,Premissas!$A$11:$B$28,2,FALSE)) -> FRQ002 | P5: =IF(O5="Sem franquia","Sem franquia","Própria") -> Própria | Q5: =VLOOKUP(E5,Premissas!$A$32:$B$35,2,FALSE) -> 938 | R5: =Q5*(1-Premissas!$B$5) -> 745.241 | S5: =IF(J5>=3,1,IF(N5="Alta",2,IF(K5=1,3,IF(N5="Média",4,5)))) -> 5 | T5: =CHOOSE(S5,"1. Fechar (lead ativo em Reunião/Proposta)","2. Prospectar tier Alta","3. Requalificar ou encerrar lead parado","4. Nutrir (marketing/inbound)","5. Régua automatizada") -> 5. Régua automatizada | U5: =COUNTIFS($O$2:$O$304,O5,$S$2:$S$304,"<"&S5)+COUNTIFS($O$2:$O$304,O5,$S$2:$S$304,S5,$R$2:$R$304,">"&R5)+1 -> 26 | V5: Médio | W5: Frio | X5: 0.2261
A6: CTD00009 | B6: MG | C6: Contagem | D6: Sudeste | E6: Autônomo | F6: 13 | G6: Nenhum | H6: Prospect em pipeline | I6: Novo | J6: 1 | K6: 0 | L6: 0 | M6: 2 | N6: Baixa | O6: =IF(B6="SP",IF(C6="São Paulo","FRQ001","FRQ002"),VLOOKUP(B6,Premissas!$A$11:$B$28,2,FALSE)) -> FRQ004 | P6: =IF(O6="Sem franquia","Sem franquia","Própria") -> Própria | Q6: =VLOOKUP(E6,Premissas!$A$32:$B$35,2,FALSE) -> 938 | R6: =Q6*(1-Premissas!$B$5) -> 745.241 | S6: =IF(J6>=3,1,IF(N6="Alta",2,IF(K6=1,3,IF(N6="Média",4,5)))) -> 5 | T6: =CHOOSE(S6,"1. Fechar (lead ativo em Reunião/Proposta)","2. Prospectar tier Alta","3. Requalificar ou encerrar lead parado","4. Nutrir (marketing/inbound)","5. Régua automatizada") -> 5. Régua automatizada | U6: =COUNTIFS($O$2:$O$304,O6,$S$2:$S$304,"<"&S6)+COUNTIFS($O$2:$O$304,O6,$S$2:$S$304,S6,$R$2:$R$304,">"&R6)+1 -> 20 | V6: Baixo | W6: Morno | X6: 0.1094
A7: CTD00011 | B7: SP | C7: São Paulo | D7: Sudeste | E7: Autônomo | F7: 19 | G7: ContaAzul | H7: Prospect sem contato | I7: Sem lead ativo | J7: 0 | K7: 0 | L7: 0 | M7: 2 | N7: Baixa | O7: =IF(B7="SP",IF(C7="São Paulo","FRQ001","FRQ002"),VLOOKUP(B7,Premissas!$A$11:$B$28,2,FALSE)) -> FRQ001 | P7: =IF(O7="Sem franquia","Sem franquia","Própria") -> Própria | Q7: =VLOOKUP(E7,Premissas!$A$32:$B$35,2,FALSE) -> 938 | R7: =Q7*(1-Premissas!$B$5) -> 745.241 | S7: =IF(J7>=3,1,IF(N7="Alta",2,IF(K7=1,3,IF(N7="Média",4,5)))) -> 5 | T7: =CHOOSE(S7,"1. Fechar (lead ativo em Reunião/Proposta)","2. Prospectar tier Alta","3. Requalificar ou encerrar lead parado","4. Nutrir (marketing/inbound)","5. Régua automatizada") -> 5. Régua automatizada | U7: =COUNTIFS($O$2:$O$304,O7,$S$2:$S$304,"<"&S7)+COUNTIFS($O$2:$O$304,O7,$S$2:$S$304,S7,$R$2:$R$304,">"&R7)+1 -> 3 | V7: Médio | W7: Frio | X7: 0.1649
A8: CTD00014 | B8: SP | C8: Campinas | D8: Sudeste | E8: Autônomo | F8: 21 | G8: Domínio | H8: Cliente Ativo | I8: Sem lead ativo | J8: 0 | K8: 0 | L8: 0 | M8: 2 | N8: Baixa | O8: =IF(B8="SP",IF(C8="São Paulo","FRQ001","FRQ002"),VLOOKUP(B8,Premissas!$A$11:$B$28,2,FALSE)) -> FRQ002 | P8: =IF(O8="Sem franquia","Sem franquia","Própria") -> Própria | Q8: =VLOOKUP(E8,Premissas!$A$32:$B$35,2,FALSE) -> 938 | R8: =Q8*(1-Premissas!$B$5) -> 745.241 | S8: =IF(J8>=3,1,IF(N8="Alta",2,IF(K8=1,3,IF(N8="Média",4,5)))) -> 5 | T8: =CHOOSE(S8,"1. Fechar (lead ativo em Reunião/Proposta)","2. Prospectar tier Alta","3. Requalificar ou encerrar lead parado","4. Nutrir (marketing/inbound)","5. Régua automatizada") -> 5. Régua automatizada | U8: =COUNTIFS($O$2:$O$304,O8,$S$2:$S$304,"<"&S8)+COUNTIFS($O$2:$O$304,O8,$S$2:$S$304,S8,$R$2:$R$304,">"&R8)+1 -> 26 | V8: Médio | W8: Frio | X8: 0.2015
A9: CTD00017 | B9: RJ | C9: Petrópolis | D9: Sudeste | E9: Autônomo | F9: 3 | G9: Nenhum | H9: Prospect em pipeline | I9: Em Contato | J9: 2 | K9: 0 | L9: 0 | M9: 2 | N9: Baixa | O9: =IF(B9="SP",IF(C9="São Paulo","FRQ001","FRQ002"),VLOOKUP(B9,Premissas!$A$11:$B$28,2,FALSE)) -> FRQ003 | P9: =IF(O9="Sem franquia","Sem franquia","Própria") -> Própria | Q9: =VLOOKUP(E9,Premissas!$A$32:$B$35,2,FALSE) -> 938 | R9: =Q9*(1-Premissas!$B$5) -> 745.241 | S9: =IF(J9>=3,1,IF(N9="Alta",2,IF(K9=1,3,IF(N9="Média",4,5)))) -> 5 | T9: =CHOOSE(S9,"1. Fechar (lead ativo em Reunião/Proposta)","2. Prospectar tier Alta","3. Requalificar ou encerrar lead parado","4. Nutrir (marketing/inbound)","5. Régua automatizada") -> 5. Régua automatizada | U9: =COUNTIFS($O$2:$O$304,O9,$S$2:$S$304,"<"&S9)+COUNTIFS($O$2:$O$304,O9,$S$2:$S$304,S9,$R$2:$R$304,">"&R9)+1 -> 31 | V9: Baixo | W9: Morno | X9: 0.1094
A10: CTD00018 | B10: SC | C10: Blumenau | D10: Sul | E10: Autônomo | F10: 14 | G10: Questor | H10: Prospect em pipeline | I10: Proposta Enviada | J10: 4 | K10: 0 | L10: 0 | M10: 3 | N10: Média | O10: =IF(B10="SP",IF(C10="São Paulo","FRQ001","FRQ002"),VLOOKUP(B10,Premissas!$A$11:$B$28,2,FALSE)) -> FRQ006 | P10: =IF(O10="Sem franquia","Sem franquia","Própria") -> Própria | Q10: =VLOOKUP(E10,Premissas!$A$32:$B$35,2,FALSE) -> 938 | R10: =Q10*(1-Premissas!$B$5) -> 745.241 | S10: =IF(J10>=3,1,IF(N10="Alta",2,IF(K10=1,3,IF(N10="Média",4,5)))) -> 1 | T10: =CHOOSE(S10,"1. Fechar (lead ativo em Reunião/Proposta)","2. Prospectar tier Alta","3. Requalificar ou encerrar lead parado","4. Nutrir (marketing/inbound)","5. Régua automatizada") -> 1. Fechar (lead ativo em Reunião/Proposta) | U10: =COUNTIFS($O$2:$O$304,O10,$S$2:$S$304,"<"&S10)+COUNTIFS($O$2:$O$304,O10,$S$2:$S$304,S10,$R$2:$R$304,">"&R10)+1 -> 1 | V10: Baixo | W10: Quente | X10: 0.1757
A11: CTD00020 | B11: SP | C11: Ribeirão Preto | D11: Sudeste | E11: Pequeno Escritório | F11: 29 | G11: Domínio | H11: Prospect sem contato | I11: Sem lead ativo | J11: 0 | K11: 0 | L11: 0 | M11: 3 | N11: Média | O11: =IF(B11="SP",IF(C11="São Paulo","FRQ001","FRQ002"),VLOOKUP(B11,Premissas!$A$11:$B$28,2,FALSE)) -> FRQ002 | P11: =IF(O11="Sem franquia","Sem franquia","Própria") -> Própria | Q11: =VLOOKUP(E11,Premissas!$A$32:$B$35,2,FALSE) -> 1121 | R11: =Q11*(1-Premissas!$B$5) -> 890.6345 | S11: =IF(J11>=3,1,IF(N11="Alta",2,IF(K11=1,3,IF(N11="Média",4,5)))) -> 4 | T11: =CHOOSE(S11,"1. Fechar (lead ativo em Reunião/Proposta)","2. Prospectar tier Alta","3. Requalificar ou encerrar lead parado","4. Nutrir (marketing/inbound)","5. Régua automatizada") -> 4. Nutrir (marketing/inbound) | U11: =COUNTIFS($O$2:$O$304,O11,$S$2:$S$304,"<"&S11)+COUNTIFS($O$2:$O$304,O11,$S$2:$S$304,S11,$R$2:$R$304,">"&R11)+1 -> 9 | V11: Alto | W11: Frio | X11: 0.3345
A12: CTD00022 | B12: GO | C12: Anápolis | D12: Centro-Oeste | E12: Pequeno Escritório | F12: 54 | G12: Totvs | H12: Prospect sem contato | I12: Sem lead ativo | J12: 0 | K12: 0 | L12: 1 | M12: 3 | N12: Média | O12: =IF(B12="SP",IF(C12="São Paulo","FRQ001","FRQ002"),VLOOKUP(B12,Premissas!$A$11:$B$28,2,FALSE)) -> FRQ009 | P12: =IF(O12="Sem franquia","Sem franquia","Própria") -> Própria | Q12: =VLOOKUP(E12,Premissas!$A$32:$B$35,2,FALSE) -> 1121 | R12: =Q12*(1-Premissas!$B$5) -> 890.6345 | S12: =IF(J12>=3,1,IF(N12="Alta",2,IF(K12=1,3,IF(N12="Média",4,5)))) -> 4 | T12: =CHOOSE(S12,"1. Fechar (lead ativo em Reunião/Proposta)","2. Prospectar tier Alta","3. Requalificar ou encerrar lead parado","4. Nutrir (marketing/inbound)","5. Régua automatizada") -> 4. Nutrir (marketing/inbound) | U12: =COUNTIFS($O$2:$O$304,O12,$S$2:$S$304,"<"&S12)+COUNTIFS($O$2:$O$304,O12,$S$2:$S$304,S12,$R$2:$R$304,">"&R12)+1 -> 4 | V12: Alto | W12: Frio | X12: 0.5462
A13: CTD00023 | B13: MG | C13: Juiz de Fora | D13: Sudeste | E13: Pequeno Escritório | F13: 18 | G13: Totvs | H13: Prospect sem contato | I13: Sem lead ativo | J13: 0 | K13: 0 | L13: 0 | M13: 2 | N13: Baixa | O13: =IF(B13="SP",IF(C13="São Paulo","FRQ001","FRQ002"),VLOOKUP(B13,Premissas!$A$11:$B$28,2,FALSE)) -> FRQ004 | P13: =IF(O13="Sem franquia","Sem franquia","Própria") -> Própria | Q13: =VLOOKUP(E13,Premissas!$A$32:$B$35,2,FALSE) -> 1121 | R13: =Q13*(1-Premissas!$B$5) -> 890.6345 | S13: =IF(J13>=3,1,IF(N13="Alta",2,IF(K13=1,3,IF(N13="Média",4,5)))) -> 5 | T13: =CHOOSE(S13,"1. Fechar (lead ativo em Reunião/Proposta)","2. Prospectar tier Alta","3. Requalificar ou encerrar lead parado","4. Nutrir (marketing/inbound)","5. Régua automatizada") -> 5. Régua automatizada | U13: =COUNTIFS($O$2:$O$304,O13,$S$2:$S$304,"<"&S13)+COUNTIFS($O$2:$O$304,O13,$S$2:$S$304,S13,$R$2:$R$304,">"&R13)+1 -> 19 | V13: Médio | W13: Frio | X13: 0.3803
... A304: CTD00596 | B304: PE | C304: Caruaru | D304: Nordeste | E304: Pequeno Escritório | F304: 49 | G304: Questor | H304: Prospect sem contato | I304: Sem lead ativo | J304: 0 | K304: 0 | L304: 0 | M304: 3 | N304: Média | O304: =IF(B304="SP",IF(C304="São Paulo","FRQ001","FRQ002"),VLOOKUP(B304,Premissas!$A$11:$B$28,2,FALSE)) -> FRQ011 | P304: =IF(O304="Sem franquia","Sem franquia","Própria") -> Própria | Q304: =VLOOKUP(E304,Premissas!$A$32:$B$35,2,FALSE) -> 1121 | R304: =Q304*(1-Premissas!$B$5) -> 890.6345 | S304: =IF(J304>=3,1,IF(N304="Alta",2,IF(K304=1,3,IF(N304="Média",4,5)))) -> 4 | T304: =CHOOSE(S304,"1. Fechar (lead ativo em Reunião/Proposta)","2. Prospectar tier Alta","3. Requalificar ou encerrar lead parado","4. Nutrir (marketing/inbound)","5. Régua automatizada") -> 4. Nutrir (marketing/inbound) | U304: =COUNTIFS($O$2:$O$304,O304,$S$2:$S$304,"<"&S304)+COUNTIFS($O$2:$O$304,O304,$S$2:$S$304,S304,$R$2:$R$304,">"&R304)+1 -> 7 | V304: Alto | W304: Frio | X304: 0.373

Sheet Ondas_Capacidade
A1: 3b — Framework de priorização: Intenção → Fit x Engajamento (1c) → Valor
A2: Ordem de ataque dentro de cada franquia: primeiro a onda (abaixo), depois o maior MRR esperado (ticket do porte × (1 − churn)). O Fit é a carteira, driver nº 3 do Desafio 2; entre os 303 prospects ela acompanha o score de propensão do D2 (correlação ~0,8, coluna X da Priorizacao). Lista completa e ordem na aba Priorizacao.
A4: Onda | B4: Quem entra | C4: O que o EC faz | D4: Por quê | E4: Critério de saída | F4: Contadores | G4: MRR esperado (R$)
A5: 1. Fechar | B5: Lead aberto há até 90 dias em Reunião Agendada ou Proposta Enviada — qualquer tier | C5: Follow-up da proposta e negociação | D5: É o único sinal real de compra; nenhum Ganho da base fechou depois de 89 dias | E5: Ganho ou Perdido com motivo | F5: =COUNTIF(Priorizacao!$S$2:$S$304,1) -> 15 | G5: =SUMIF(Priorizacao!$S$2:$S$304,1,Priorizacao!$R$2:$R$304) -> 11760.189
A6: 2. Prospectar tier Alta | B6: Tier Alta do Desafio 1c (Fit Alto + Morno) que não está na Onda 1 | C6: Outbound do EC: diagnóstico e reunião | D6: Carteira acima de 24 clientes (driver do D2, acompanha a propensão) e lead em andamento | E6: Reunião ou descarte | F6: =COUNTIF(Priorizacao!$S$2:$S$304,2) -> 13 | G6: =SUMIF(Priorizacao!$S$2:$S$304,2,Priorizacao!$R$2:$R$304) -> 11432.855
A7: 3. Requalificar parado | B7: Lead aberto há mais de 90 dias (fora das ondas 1 e 2) | C7: Uma tentativa de requalificação; sem avanço, encerrar como Perdido | D7: Lead com mais de 89 dias nunca virou Ganho na base: limpar libera tempo de EC | E7: Lead volta a ativo ou é encerrado | F7: =COUNTIF(Priorizacao!$S$2:$S$304,3) -> 54 | G7: =SUMIF(Priorizacao!$S$2:$S$304,3,Priorizacao!$R$2:$R$304) -> 43477.424
A8: 4. Nutrir | B8: Tier Média fora das ondas 1 a 3 | C8: Marketing (conteúdo, eventos, inbound); EC só se o contador levantar a mão | D8: Fit ou engajamento parcial: ainda não justifica tempo de EC | E8: Pedido de contato → Onda 2 | F8: =COUNTIF(Priorizacao!$S$2:$S$304,4) -> 66 | G8: =SUMIF(Priorizacao!$S$2:$S$304,4,Priorizacao!$R$2:$R$304) -> 57709.302
A9: 5. Régua automatizada | B9: Tier Baixa fora das ondas 1 a 3 | C9: Comunicação automatizada, sem tempo de EC | D9: Sem fit e sem engajamento | E9: Resposta → requalificar | F9: =COUNTIF(Priorizacao!$S$2:$S$304,5) -> 155 | G9: =SUMIF(Priorizacao!$S$2:$S$304,5,Priorizacao!$R$2:$R$304) -> 116820.9
E10: Total | F10: =SUM(F5:F9) -> 303 | G10: =SUM(G5:G9) -> 241200.67
A13: Carga das ondas 1-3 (as que consomem tempo de EC) vs capacidade mensal por franquia
A14: id | B14: Franquia | C14: ECs | D14: Capacidade (leads/mês) | E14: Onda 1 | F14: Onda 2 | G14: Onda 3 | H14: Ondas 1-3 | I14: % da capacidade de 1 mês | J14: MRR esperado ondas 1-2 (R$) | K14: Onda 4 | L14: Onda 5
A15: =Gap_Meta!A5 -> FRQ001 | B15: =Gap_Meta!B5 -> Franquia SP Capital | C15: =Gap_Meta!F5 -> 6 | D15: =C15*Premissas!$B$4 -> 99 | E15: =COUNTIFS(Priorizacao!$O$2:$O$304,$A15,Priorizacao!$S$2:$S$304,1) -> 0 | F15: =COUNTIFS(Priorizacao!$O$2:$O$304,$A15,Priorizacao!$S$2:$S$304,2) -> 0 | G15: =COUNTIFS(Priorizacao!$O$2:$O$304,$A15,Priorizacao!$S$2:$S$304,3) -> 2 | H15: =SUM(E15:G15) -> 2 | I15: =H15/D15 -> 0.02020202 | J15: =SUMIFS(Priorizacao!$R$2:$R$304,Priorizacao!$O$2:$O$304,$A15,Priorizacao!$S$2:$S$304,1)+SUMIFS(Priorizacao!$R$2:$R$304,Priorizacao!$O$2:$O$304,$A15,Priorizacao!$S$2:$S$304,2) -> 0 | K15: =COUNTIFS(Priorizacao!$O$2:$O$304,$A15,Priorizacao!$S$2:$S$304,4) -> 0 | L15: =COUNTIFS(Priorizacao!$O$2:$O$304,$A15,Priorizacao!$S$2:$S$304,5) -> 4
A16: =Gap_Meta!A6 -> FRQ002 | B16: =Gap_Meta!B6 -> Franquia SP Interior | C16: =Gap_Meta!F6 -> 4 | D16: =C16*Premissas!$B$4 -> 66 | E16: =COUNTIFS(Priorizacao!$O$2:$O$304,$A16,Priorizacao!$S$2:$S$304,1) -> 3 | F16: =COUNTIFS(Priorizacao!$O$2:$O$304,$A16,Priorizacao!$S$2:$S$304,2) -> 0 | G16: =COUNTIFS(Priorizacao!$O$2:$O$304,$A16,Priorizacao!$S$2:$S$304,3) -> 5 | H16: =SUM(E16:G16) -> 8 | I16: =H16/D16 -> 0.12121212 | J16: =SUMIFS(Priorizacao!$R$2:$R$304,Priorizacao!$O$2:$O$304,$A16,Priorizacao!$S$2:$S$304,1)+SUMIFS(Priorizacao!$R$2:$R$304,Priorizacao!$O$2:$O$304,$A16,Priorizacao!$S$2:$S$304,2) -> 2526.51 | K16: =COUNTIFS(Priorizacao!$O$2:$O$304,$A16,Priorizacao!$S$2:$S$304,4) -> 13 | L16: =COUNTIFS(Priorizacao!$O$2:$O$304,$A16,Priorizacao!$S$2:$S$304,5) -> 31
A17: =Gap_Meta!A7 -> FRQ003 | B17: =Gap_Meta!B7 -> Franquia RJ | C17: =Gap_Meta!F7 -> 5 | D17: =C17*Premissas!$B$4 -> 82.5 | E17: =COUNTIFS(Priorizacao!$O$2:$O$304,$A17,Priorizacao!$S$2:$S$304,1) -> 4 | F17: =COUNTIFS(Priorizacao!$O$2:$O$304,$A17,Priorizacao!$S$2:$S$304,2) -> 4 | G17: =COUNTIFS(Priorizacao!$O$2:$O$304,$A17,Priorizacao!$S$2:$S$304,3) -> 5 | H17: =SUM(E17:G17) -> 13 | I17: =H17/D17 -> 0.15757576 | J17: =SUMIFS(Priorizacao!$R$2:$R$304,Priorizacao!$O$2:$O$304,$A17,Priorizacao!$S$2:$S$304,1)+SUMIFS(Priorizacao!$R$2:$R$304,Priorizacao!$O$2:$O$304,$A17,Priorizacao!$S$2:$S$304,2) -> 6543.502 | K17: =COUNTIFS(Priorizacao!$O$2:$O$304,$A17,Priorizacao!$S$2:$S$304,4) -> 17 | L17: =COUNTIFS(Priorizacao!$O$2:$O$304,$A17,Priorizacao!$S$2:$S$304,5) -> 23
A18: =Gap_Meta!A8 -> FRQ004 | B18: =Gap_Meta!B8 -> Franquia MG | C18: =Gap_Meta!F8 -> 3 | D18: =C18*Premissas!$B$4 -> 49.5 | E18: =COUNTIFS(Priorizacao!$O$2:$O$304,$A18,Priorizacao!$S$2:$S$304,1) -> 2 | F18: =COUNTIFS(Priorizacao!$O$2:$O$304,$A18,Priorizacao!$S$2:$S$304,2) -> 1 | G18: =COUNTIFS(Priorizacao!$O$2:$O$304,$A18,Priorizacao!$S$2:$S$304,3) -> 6 | H18: =SUM(E18:G18) -> 9 | I18: =H18/D18 -> 0.18181818 | J18: =SUMIFS(Priorizacao!$R$2:$R$304,Priorizacao!$O$2:$O$304,$A18,Priorizacao!$S$2:$S$304,1)+SUMIFS(Priorizacao!$R$2:$R$304,Priorizacao!$O$2:$O$304,$A18,Priorizacao!$S$2:$S$304,2) -> 2526.51 | K18: =COUNTIFS(Priorizacao!$O$2:$O$304,$A18,Priorizacao!$S$2:$S$304,4) -> 9 | L18: =COUNTIFS(Priorizacao!$O$2:$O$304,$A18,Priorizacao!$S$2:$S$304,5) -> 14
A19: =Gap_Meta!A9 -> FRQ005 | B19: =Gap_Meta!B9 -> Franquia PR | C19: =Gap_Meta!F9 -> 5 | D19: =C19*Premissas!$B$4 -> 82.5 | E19: =COUNTIFS(Priorizacao!$O$2:$O$304,$A19,Priorizacao!$S$2:$S$304,1) -> 2 | F19: =COUNTIFS(Priorizacao!$O$2:$O$304,$A19,Priorizacao!$S$2:$S$304,2) -> 1 | G19: =COUNTIFS(Priorizacao!$O$2:$O$304,$A19,Priorizacao!$S$2:$S$304,3) -> 3 | H19: =SUM(E19:G19) -> 6 | I19: =H19/D19 -> 0.072727273 | J19: =SUMIFS(Priorizacao!$R$2:$R$304,Priorizacao!$O$2:$O$304,$A19,Priorizacao!$S$2:$S$304,1)+SUMIFS(Priorizacao!$R$2:$R$304,Priorizacao!$O$2:$O$304,$A19,Priorizacao!$S$2:$S$304,2) -> 2381.1165 | K19: =COUNTIFS(Priorizacao!$O$2:$O$304,$A19,Priorizacao!$S$2:$S$304,4) -> 1 | L19: =COUNTIFS(Priorizacao!$O$2:$O$304,$A19,Priorizacao!$S$2:$S$304,5) -> 9
A20: =Gap_Meta!A10 -> FRQ006 | B20: =Gap_Meta!B10 -> Franquia SC | C20: =Gap_Meta!F10 -> 3 | D20: =C20*Premissas!$B$4 -> 49.5 | E20: =COUNTIFS(Priorizacao!$O$2:$O$304,$A20,Priorizacao!$S$2:$S$304,1) -> 1 | F20: =COUNTIFS(Priorizacao!$O$2:$O$304,$A20,Priorizacao!$S$2:$S$304,2) -> 1 | G20: =COUNTIFS(Priorizacao!$O$2:$O$304,$A20,Priorizacao!$S$2:$S$304,3) -> 2 | H20: =SUM(E20:G20) -> 4 | I20: =H20/D20 -> 0.080808081 | J20: =SUMIFS(Priorizacao!$R$2:$R$304,Priorizacao!$O$2:$O$304,$A20,Priorizacao!$S$2:$S$304,1)+SUMIFS(Priorizacao!$R$2:$R$304,Priorizacao!$O$2:$O$304,$A20,Priorizacao!$S$2:$S$304,2) -> 1635.8755 | K20: =COUNTIFS(Priorizacao!$O$2:$O$304,$A20,Priorizacao!$S$2:$S$304,4) -> 1 | L20: =COUNTIFS(Priorizacao!$O$2:$O$304,$A20,Priorizacao!$S$2:$S$304,5) -> 6
A21: =Gap_Meta!A11 -> FRQ007 | B21: =Gap_Meta!B11 -> Franquia RS | C21: =Gap_Meta!F11 -> 4 | D21: =C21*Premissas!$B$4 -> 66 | E21: =COUNTIFS(Priorizacao!$O$2:$O$304,$A21,Priorizacao!$S$2:$S$304,1) -> 1 | F21: =COUNTIFS(Priorizacao!$O$2:$O$304,$A21,Priorizacao!$S$2:$S$304,2) -> 0 | G21: =COUNTIFS(Priorizacao!$O$2:$O$304,$A21,Priorizacao!$S$2:$S$304,3) -> 2 | H21: =SUM(E21:G21) -> 3 | I21: =H21/D21 -> 0.045454545 | J21: =SUMIFS(Priorizacao!$R$2:$R$304,Priorizacao!$O$2:$O$304,$A21,Priorizacao!$S$2:$S$304,1)+SUMIFS(Priorizacao!$R$2:$R$304,Priorizacao!$O$2:$O$304,$A21,Priorizacao!$S$2:$S$304,2) -> 745.241 | K21: =COUNTIFS(Priorizacao!$O$2:$O$304,$A21,Priorizacao!$S$2:$S$304,4) -> 0 | L21: =COUNTIFS(Priorizacao!$O$2:$O$304,$A21,Priorizacao!$S$2:$S$304,5) -> 10
A22: =Gap_Meta!A12 -> FRQ008 | B22: =Gap_Meta!B12 -> Franquia DF | C22: =Gap_Meta!F12 -> 3 | D22: =C22*Premissas!$B$4 -> 49.5 | E22: =COUNTIFS(Priorizacao!$O$2:$O$304,$A22,Priorizacao!$S$2:$S$304,1) -> 0 | F22: =COUNTIFS(Priorizacao!$O$2:$O$304,$A22,Priorizacao!$S$2:$S$304,2) -> 0 | G22: =COUNTIFS(Priorizacao!$O$2:$O$304,$A22,Priorizacao!$S$2:$S$304,3) -> 2 | H22: =SUM(E22:G22) -> 2 | I22: =H22/D22 -> 0.04040404 | J22: =SUMIFS(Priorizacao!$R$2:$R$304,Priorizacao!$O$2:$O$304,$A22,Priorizacao!$S$2:$S$304,1)+SUMIFS(Priorizacao!$R$2:$R$304,Priorizacao!$O$2:$O$304,$A22,Priorizacao!$S$2:$S$304,2) -> 0 | K22: =COUNTIFS(Priorizacao!$O$2:$O$304,$A22,Priorizacao!$S$2:$S$304,4) -> 3 | L22: =COUNTIFS(Priorizacao!$O$2:$O$304,$A22,Priorizacao!$S$2:$S$304,5) -> 6
A23: =Gap_Meta!A13 -> FRQ009 | B23: =Gap_Meta!B13 -> Franquia GO | C23: =Gap_Meta!F13 -> 2 | D23: =C23*Premissas!$B$4 -> 33 | E23: =COUNTIFS(Priorizacao!$O$2:$O$304,$A23,Priorizacao!$S$2:$S$304,1) -> 0 | F23: =COUNTIFS(Priorizacao!$O$2:$O$304,$A23,Priorizacao!$S$2:$S$304,2) -> 0 | G23: =COUNTIFS(Priorizacao!$O$2:$O$304,$A23,Priorizacao!$S$2:$S$304,3) -> 3 | H23: =SUM(E23:G23) -> 3 | I23: =H23/D23 -> 0.090909091 | J23: =SUMIFS(Priorizacao!$R$2:$R$304,Priorizacao!$O$2:$O$304,$A23,Priorizacao!$S$2:$S$304,1)+SUMIFS(Priorizacao!$R$2:$R$304,Priorizacao!$O$2:$O$304,$A23,Priorizacao!$S$2:$S$304,2) -> 0 | K23: =COUNTIFS(Priorizacao!$O$2:$O$304,$A23,Priorizacao!$S$2:$S$304,4) -> 2 | L23: =COUNTIFS(Priorizacao!$O$2:$O$304,$A23,Priorizacao!$S$2:$S$304,5) -> 6
A24: =Gap_Meta!A14 -> FRQ010 | B24: =Gap_Meta!B14 -> Franquia BA | C24: =Gap_Meta!F14 -> 2 | D24: =C24*Premissas!$B$4 -> 33 | E24: =COUNTIFS(Priorizacao!$O$2:$O$304,$A24,Priorizacao!$S$2:$S$304,1) -> 0 | F24: =COUNTIFS(Priorizacao!$O$2:$O$304,$A24,Priorizacao!$S$2:$S$304,2) -> 1 | G24: =COUNTIFS(Priorizacao!$O$2:$O$304,$A24,Priorizacao!$S$2:$S$304,3) -> 5 | H24: =SUM(E24:G24) -> 6 | I24: =H24/D24 -> 0.18181818 | J24: =SUMIFS(Priorizacao!$R$2:$R$304,Priorizacao!$O$2:$O$304,$A24,Priorizacao!$S$2:$S$304,1)+SUMIFS(Priorizacao!$R$2:$R$304,Priorizacao!$O$2:$O$304,$A24,Priorizacao!$S$2:$S$304,2) -> 890.6345 | K24: =COUNTIFS(Priorizacao!$O$2:$O$304,$A24,Priorizacao!$S$2:$S$304,4) -> 3 | L24: =COUNTIFS(Priorizacao!$O$2:$O$304,$A24,Priorizacao!$S$2:$S$304,5) -> 16
A25: =Gap_Meta!A15 -> FRQ011 | B25: =Gap_Meta!B15 -> Franquia PE | C25: =Gap_Meta!F15 -> 2 | D25: =C25*Premissas!$B$4 -> 33 | E25: =COUNTIFS(Priorizacao!$O$2:$O$304,$A25,Priorizacao!$S$2:$S$304,1) -> 1 | F25: =COUNTIFS(Priorizacao!$O$2:$O$304,$A25,Priorizacao!$S$2:$S$304,2) -> 1 | G25: =COUNTIFS(Priorizacao!$O$2:$O$304,$A25,Priorizacao!$S$2:$S$304,3) -> 4 | H25: =SUM(E25:G25) -> 6 | I25: =H25/D25 -> 0.18181818 | J25: =SUMIFS(Priorizacao!$R$2:$R$304,Priorizacao!$O$2:$O$304,$A25,Priorizacao!$S$2:$S$304,1)+SUMIFS(Priorizacao!$R$2:$R$304,Priorizacao!$O$2:$O$304,$A25,Priorizacao!$S$2:$S$304,2) -> 1635.8755 | K25: =COUNTIFS(Priorizacao!$O$2:$O$304,$A25,Priorizacao!$S$2:$S$304,4) -> 7 | L25: =COUNTIFS(Priorizacao!$O$2:$O$304,$A25,Priorizacao!$S$2:$S$304,5) -> 3
A26: =Gap_Meta!A16 -> FRQ012 | B26: =Gap_Meta!B16 -> Franquia CE | C26: =Gap_Meta!F16 -> 1 | D26: =C26*Premissas!$B$4 -> 16.5 | E26: =COUNTIFS(Priorizacao!$O$2:$O$304,$A26,Priorizacao!$S$2:$S$304,1) -> 0 | F26: =COUNTIFS(Priorizacao!$O$2:$O$304,$A26,Priorizacao!$S$2:$S$304,2) -> 0 | G26: =COUNTIFS(Priorizacao!$O$2:$O$304,$A26,Priorizacao!$S$2:$S$304,3) -> 1 | H26: =SUM(E26:G26) -> 1 | I26: =H26/D26 -> 0.060606061 | J26: =SUMIFS(Priorizacao!$R$2:$R$304,Priorizacao!$O$2:$O$304,$A26,Priorizacao!$S$2:$S$304,1)+SUMIFS(Priorizacao!$R$2:$R$304,Priorizacao!$O$2:$O$304,$A26,Priorizacao!$S$2:$S$304,2) -> 0 | K26: =COUNTIFS(Priorizacao!$O$2:$O$304,$A26,Priorizacao!$S$2:$S$304,4) -> 2 | L26: =COUNTIFS(Priorizacao!$O$2:$O$304,$A26,Priorizacao!$S$2:$S$304,5) -> 3
... A29: =Gap_Meta!A19 -> FRQ015 | B29: =Gap_Meta!B19 -> Franquia ES | C29: =Gap_Meta!F19 -> 2 | D29: =C29*Premissas!$B$4 -> 33 | E29: =COUNTIFS(Priorizacao!$O$2:$O$304,$A29,Priorizacao!$S$2:$S$304,1) -> 0 | F29: =COUNTIFS(Priorizacao!$O$2:$O$304,$A29,Priorizacao!$S$2:$S$304,2) -> 0 | G29: =COUNTIFS(Priorizacao!$O$2:$O$304,$A29,Priorizacao!$S$2:$S$304,3) -> 4 | H29: =SUM(E29:G29) -> 4 | I29: =H29/D29 -> 0.12121212 | J29: =SUMIFS(Priorizacao!$R$2:$R$304,Priorizacao!$O$2:$O$304,$A29,Priorizacao!$S$2:$S$304,1)+SUMIFS(Priorizacao!$R$2:$R$304,Priorizacao!$O$2:$O$304,$A29,Priorizacao!$S$2:$S$304,2) -> 0 | K29: =COUNTIFS(Priorizacao!$O$2:$O$304,$A29,Priorizacao!$S$2:$S$304,4) -> 3 | L29: =COUNTIFS(Priorizacao!$O$2:$O$304,$A29,Priorizacao!$S$2:$S$304,5) -> 6
A31: Leitura
A32: • Intenção primeiro: a Onda 1 é o único grupo com sinal real de compra (lead ativo em estágio avançado).
A33: • O tier Alta vem em seguida, mas o perfil precisa ser validado: rodar as Ondas 1-2 como piloto com grupo de controle (Desafio 2).
A34: • A Onda 3 libera capacidade: limpar leads parados devolve horas de EC e torna a cobertura de pipeline confiável.
A35: • Contadores em estados sem franquia (MT, MA, RO, MS) ficam fora da tabela por franquia: não há EC responsável.
A36: • A capacidade nominal (44 ECs × 16,5 leads/mês ≈ 726 leads) supera os 303 endereçáveis da base. O que importa é a ORDEM de ataque, não a falta de capacidade.

Sheet EC_Adicional
A1: 3c — Onde alocar 1 EC adicional?
A2: Critério (só dados da base): o EC vai para onde há mais fechamentos potenciais por EC = endereçáveis do território por EC × conversão lead → fechamento da própria franquia (execucao_comercial). Sensibilidade: ranking refeito só pela demanda e só pela conversão.
A4: id | B4: Franquia | C4: Meses de operação | D4: ECs | E4: Endereçáveis no território | F4: Endereçáveis por EC | G4: Conversão lead → fechamento | H4: Fechamentos potenciais por EC | I4: Gap (R$) | J4: Atingimento | K4: Realizado por EC | L4: Ranking (fechamentos potenciais) | M4: Ranking (demanda por EC) | N4: Ranking (conversão) | O4: Leads trabalhados por EC-mês (carga)
A5: =Gap_Meta!A5 -> FRQ001 | B5: =Gap_Meta!B5 -> Franquia SP Capital | C5: =Gap_Meta!E5 -> 18 | D5: =Gap_Meta!F5 -> 6 | E5: =COUNTIF(Priorizacao!$O$2:$O$304,A5) -> 6 | F5: =E5/D5 -> 1 | G5: =Gap_Meta!Q5/Gap_Meta!N5 -> 0.038528897 | H5: =F5*G5 -> 0.038528897 | I5: =Gap_Meta!J5 -> 0 | J5: =Gap_Meta!I5 -> 1.1555556 | K5: =Gap_Meta!L5 -> 8666.6667 | L5: =RANK(H5,$H$5:$H$19) -> 15 | M5: =RANK(F5,$F$5:$F$19) -> 15 | N5: =RANK(G5,$G$5:$G$19) -> 11 | O5: =AVERAGEIFS(Execucao!$E$2:$E$529,Execucao!$B$2:$B$529,A5) -> 15.861111
A6: =Gap_Meta!A6 -> FRQ002 | B6: =Gap_Meta!B6 -> Franquia SP Interior | C6: =Gap_Meta!E6 -> 12 | D6: =Gap_Meta!F6 -> 4 | E6: =COUNTIF(Priorizacao!$O$2:$O$304,A6) -> 52 | F6: =E6/D6 -> 13 | G6: =Gap_Meta!Q6/Gap_Meta!N6 -> 0.029150824 | H6: =F6*G6 -> 0.37896071 | I6: =Gap_Meta!J6 -> 0 | J6: =Gap_Meta!I6 -> 1.1071429 | K6: =Gap_Meta!L6 -> 7750 | L6: =RANK(H6,$H$5:$H$19) -> 4 | M6: =RANK(F6,$F$5:$F$19) -> 1 | N6: =RANK(G6,$G$5:$G$19) -> 14 | O6: =AVERAGEIFS(Execucao!$E$2:$E$529,Execucao!$B$2:$B$529,A6) -> 16.4375
A7: =Gap_Meta!A7 -> FRQ003 | B7: =Gap_Meta!B7 -> Franquia RJ | C7: =Gap_Meta!E7 -> 14 | D7: =Gap_Meta!F7 -> 5 | E7: =COUNTIF(Priorizacao!$O$2:$O$304,A7) -> 53 | F7: =E7/D7 -> 10.6 | G7: =Gap_Meta!Q7/Gap_Meta!N7 -> 0.040322581 | H7: =F7*G7 -> 0.42741935 | I7: =Gap_Meta!J7 -> 4000 | J7: =Gap_Meta!I7 -> 0.875 | K7: =Gap_Meta!L7 -> 5600 | L7: =RANK(H7,$H$5:$H$19) -> 3 | M7: =RANK(F7,$F$5:$F$19) -> 4 | N7: =RANK(G7,$G$5:$G$19) -> 9 | O7: =AVERAGEIFS(Execucao!$E$2:$E$529,Execucao!$B$2:$B$529,A7) -> 16.533333
A8: =Gap_Meta!A8 -> FRQ004 | B8: =Gap_Meta!B8 -> Franquia MG | C8: =Gap_Meta!E8 -> 10 | D8: =Gap_Meta!F8 -> 3 | E8: =COUNTIF(Priorizacao!$O$2:$O$304,A8) -> 32 | F8: =E8/D8 -> 10.666667 | G8: =Gap_Meta!Q8/Gap_Meta!N8 -> 0.047217538 | H8: =F8*G8 -> 0.50365374 | I8: =Gap_Meta!J8 -> 0 | J8: =Gap_Meta!I8 -> 1.1363636 | K8: =Gap_Meta!L8 -> 8333.3333 | L8: =RANK(H8,$H$5:$H$19) -> 2 | M8: =RANK(F8,$F$5:$F$19) -> 3 | N8: =RANK(G8,$G$5:$G$19) -> 2 | O8: =AVERAGEIFS(Execucao!$E$2:$E$529,Execucao!$B$2:$B$529,A8) -> 16.472222
A9: =Gap_Meta!A9 -> FRQ005 | B9: =Gap_Meta!B9 -> Franquia PR | C9: =Gap_Meta!E9 -> 16 | D9: =Gap_Meta!F9 -> 5 | E9: =COUNTIF(Priorizacao!$O$2:$O$304,A9) -> 16 | F9: =E9/D9 -> 3.2 | G9: =Gap_Meta!Q9/Gap_Meta!N9 -> 0.03567788 | H9: =F9*G9 -> 0.11416922 | I9: =Gap_Meta!J9 -> 0 | J9: =Gap_Meta!I9 -> 1.1333333 | K9: =Gap_Meta!L9 -> 6800 | L9: =RANK(H9,$H$5:$H$19) -> 14 | M9: =RANK(F9,$F$5:$F$19) -> 14 | N9: =RANK(G9,$G$5:$G$19) -> 13 | O9: =AVERAGEIFS(Execucao!$E$2:$E$529,Execucao!$B$2:$B$529,A9) -> 16.35
A10: =Gap_Meta!A10 -> FRQ006 | B10: =Gap_Meta!B10 -> Franquia SC | C10: =Gap_Meta!E10 -> 8 | D10: =Gap_Meta!F10 -> 3 | E10: =COUNTIF(Priorizacao!$O$2:$O$304,A10) -> 11 | F10: =E10/D10 -> 3.6666667 | G10: =Gap_Meta!Q10/Gap_Meta!N10 -> 0.041666667 | H10: =F10*G10 -> 0.15277778 | I10: =Gap_Meta!J10 -> 0 | J10: =Gap_Meta!I10 -> 1.1666667 | K10: =Gap_Meta!L10 -> 7000 | L10: =RANK(H10,$H$5:$H$19) -> 10 | M10: =RANK(F10,$F$5:$F$19) -> 11 | N10: =RANK(G10,$G$5:$G$19) -> 5 | O10: =AVERAGEIFS(Execucao!$E$2:$E$529,Execucao!$B$2:$B$529,A10) -> 16
A11: =Gap_Meta!A11 -> FRQ007 | B11: =Gap_Meta!B11 -> Franquia RS | C11: =Gap_Meta!E11 -> 11 | D11: =Gap_Meta!F11 -> 4 | E11: =COUNTIF(Priorizacao!$O$2:$O$304,A11) -> 13 | F11: =E11/D11 -> 3.25 | G11: =Gap_Meta!Q11/Gap_Meta!N11 -> 0.037647059 | H11: =F11*G11 -> 0.12235294 | I11: =Gap_Meta!J11 -> 1000 | J11: =Gap_Meta!I11 -> 0.95833333 | K11: =Gap_Meta!L11 -> 5750 | L11: =RANK(H11,$H$5:$H$19) -> 12 | M11: =RANK(F11,$F$5:$F$19) -> 13 | N11: =RANK(G11,$G$5:$G$19) -> 12 | O11: =AVERAGEIFS(Execucao!$E$2:$E$529,Execucao!$B$2:$B$529,A11) -> 17.708333
A12: =Gap_Meta!A12 -> FRQ008 | B12: =Gap_Meta!B12 -> Franquia DF | C12: =Gap_Meta!E12 -> 9 | D12: =Gap_Meta!F12 -> 3 | E12: =COUNTIF(Priorizacao!$O$2:$O$304,A12) -> 11 | F12: =E12/D12 -> 3.6666667 | G12: =Gap_Meta!Q12/Gap_Meta!N12 -> 0.041144902 | H12: =F12*G12 -> 0.15086464 | I12: =Gap_Meta!J12 -> 2000 | J12: =Gap_Meta!I12 -> 0.9 | K12: =Gap_Meta!L12 -> 6000 | L12: =RANK(H12,$H$5:$H$19) -> 11 | M12: =RANK(F12,$F$5:$F$19) -> 11 | N12: =RANK(G12,$G$5:$G$19) -> 8 | O12: =AVERAGEIFS(Execucao!$E$2:$E$529,Execucao!$B$2:$B$529,A12) -> 15.527778
A13: =Gap_Meta!A13 -> FRQ009 | B13: =Gap_Meta!B13 -> Franquia GO | C13: =Gap_Meta!E13 -> 7 | D13: =Gap_Meta!F13 -> 2 | E13: =COUNTIF(Priorizacao!$O$2:$O$304,A13) -> 11 | F13: =E13/D13 -> 5.5 | G13: =Gap_Meta!Q13/Gap_Meta!N13 -> 0.041463415 | H13: =F13*G13 -> 0.22804878 | I13: =Gap_Meta!J13 -> 2000 | J13: =Gap_Meta!I13 -> 0.875 | K13: =Gap_Meta!L13 -> 7000 | L13: =RANK(H13,$H$5:$H$19) -> 9 | M13: =RANK(F13,$F$5:$F$19) -> 9 | N13: =RANK(G13,$G$5:$G$19) -> 6 | O13: =AVERAGEIFS(Execucao!$E$2:$E$529,Execucao!$B$2:$B$529,A13) -> 17.083333
A14: =Gap_Meta!A14 -> FRQ010 | B14: =Gap_Meta!B14 -> Franquia BA | C14: =Gap_Meta!E14 -> 6 | D14: =Gap_Meta!F14 -> 2 | E14: =COUNTIF(Priorizacao!$O$2:$O$304,A14) -> 25 | F14: =E14/D14 -> 12.5 | G14: =Gap_Meta!Q14/Gap_Meta!N14 -> 0.044642857 | H14: =F14*G14 -> 0.55803571 | I14: =Gap_Meta!J14 -> 3000 | J14: =Gap_Meta!I14 -> 0.78571429 | K14: =Gap_Meta!L14 -> 5500 | L14: =RANK(H14,$H$5:$H$19) -> 1 | M14: =RANK(F14,$F$5:$F$19) -> 2 | N14: =RANK(G14,$G$5:$G$19) -> 3 | O14: =AVERAGEIFS(Execucao!$E$2:$E$529,Execucao!$B$2:$B$529,A14) -> 18.666667
A15: =Gap_Meta!A15 -> FRQ011 | B15: =Gap_Meta!B15 -> Franquia PE | C15: =Gap_Meta!E15 -> 5 | D15: =Gap_Meta!F15 -> 2 | E15: =COUNTIF(Priorizacao!$O$2:$O$304,A15) -> 16 | F15: =E15/D15 -> 8 | G15: =Gap_Meta!Q15/Gap_Meta!N15 -> 0.044502618 | H15: =F15*G15 -> 0.35602094 | I15: =Gap_Meta!J15 -> 2000 | J15: =Gap_Meta!I15 -> 0.83333333 | K15: =Gap_Meta!L15 -> 5000 | L15: =RANK(H15,$H$5:$H$19) -> 6 | M15: =RANK(F15,$F$5:$F$19) -> 5 | N15: =RANK(G15,$G$5:$G$19) -> 4 | O15: =AVERAGEIFS(Execucao!$E$2:$E$529,Execucao!$B$2:$B$529,A15) -> 15.916667
A16: =Gap_Meta!A16 -> FRQ012 | B16: =Gap_Meta!B16 -> Franquia CE | C16: =Gap_Meta!E16 -> 4 | D16: =Gap_Meta!F16 -> 1 | E16: =COUNTIF(Priorizacao!$O$2:$O$304,A16) -> 6 | F16: =E16/D16 -> 6 | G16: =Gap_Meta!Q16/Gap_Meta!N16 -> 0.041237113 | H16: =F16*G16 -> 0.24742268 | I16: =Gap_Meta!J16 -> 1500 | J16: =Gap_Meta!I16 -> 0.85 | K16: =Gap_Meta!L16 -> 8500 | L16: =RANK(H16,$H$5:$H$19) -> 8 | M16: =RANK(F16,$F$5:$F$19) -> 8 | N16: =RANK(G16,$G$5:$G$19) -> 7 | O16: =AVERAGEIFS(Execucao!$E$2:$E$529,Execucao!$B$2:$B$529,A16) -> 16.166667
... A19: =Gap_Meta!A19 -> FRQ015 | B19: =Gap_Meta!B19 -> Franquia ES | C19: =Gap_Meta!E19 -> 5 | D19: =Gap_Meta!F19 -> 2 | E19: =COUNTIF(Priorizacao!$O$2:$O$304,A19) -> 13 | F19: =E19/D19 -> 6.5 | G19: =Gap_Meta!Q19/Gap_Meta!N19 -> 0.055555556 | H19: =F19*G19 -> 0.36111111 | I19: =Gap_Meta!J19 -> 0 | J19: =Gap_Meta!I19 -> 1.0909091 | K19: =Gap_Meta!L19 -> 6000 | L19: =RANK(H19,$H$5:$H$19) -> 5 | M19: =RANK(F19,$F$5:$F$19) -> 7 | N19: =RANK(G19,$G$5:$G$19) -> 1 | O19: =AVERAGEIFS(Execucao!$E$2:$E$529,Execucao!$B$2:$B$529,A19) -> 16.5
A21: Recomendação
A22: Franquia recomendada (ranking 1) | D22: =INDEX($B$5:$B$19,MATCH(1,$L$5:$L$19,0)) -> Franquia BA
A23: 2ª opção | D23: =INDEX($B$5:$B$19,MATCH(2,$L$5:$L$19,0)) -> Franquia MG
A24: Por quê (franquia recomendada) | D24: =FIXED(INDEX($F$5:$F$19,MATCH(1,$L$5:$L$19,0)),1)&" endereçáveis por EC (rede: "&FIXED(SUM($E$5:$E$19)/SUM($D$5:$D$19),1)&"), conversão do funil de "&FIXED(INDEX($G$5:$G$19,MATCH(1,$L$5:$L$19,0))*100,1)&"% (rede: "&FIXED(Gap_Meta!Q20/Gap_Meta!N20*100,1)&"%), ECs com "&FIXED(INDEX($O$5:$O$19,MATCH(1,$L$5:$L$19,0)),1)&" leads trabalhados por mês (rede: "&FIXED(AVERAGE(Execucao!$E$2:$E$529),1)&") e gap de R$ "&FIXED(INDEX($I$5:$I$19,MATCH(1,$L$5:$L$19,0)),0) -> 12,5 endereçáveis por EC (rede: 6,3), conversão do funil de 4,5% (rede: 4,0%), ECs com 18,7 leads trabalhados por mês (rede: 16,5) e gap de R$ 3.000
